File: data/20210331-3_2V032701 Fe60m center2.ras
*RAS_DATA_START
*RAS_HEADER_START
*DISP_FMT_X "%.3f"
*DISP_FMT_Y "%.0f"
*DISP_FULLSCALE "47557792.4000000060"
*DISP_LINE_COLOR "255.0000000000"
*DISP_LINE_STYLE "0.0000000000"
*DISP_LINE_WIDTH "0.2500000000"
*DISP_NOTE "測定データ-10"
*DISP_OFFSET_Y "0.0000000000"
*DISP_PEAKSEARCH_UNIT_Y "cps"
*DISP_RANGE_BOTTOM "0.0100000000"
*DISP_RANGE_LEFT "0.0000000000"
*DISP_RANGE_LOGCUTOFF "0.0100000000"
*DISP_RANGE_RIGHT "6.0000000000"
*DISP_RANGE_TOP "47557792.4000000060"
*DISP_SCALE_MODE_Y "2.0000000000"
*DISP_TAB_NAME "2θ/ω"
*DISP_TITLE_Y "強度"
*DISP_UNIT_Y "cps"
*DISP_WINDOW_NAME "MSG_MACROENGINE"
*FILE_COMMENT " "
*FILE_MD5 ""
*FILE_MEMO "600 120mA 150V -16deg phi460(6t)"
*FILE_OPERATOR "User1"
*FILE_PART_ID "MEAS_KHP2_00055"
*FILE_SAMPLE "2V032701 Fe60m center2"
*FILE_TYPE "RAS_RAW"
*FILE_USERGROUP "システムマネージャ"
*FILE_VERSION "1.0000000000"
*HW_ATTACHMENT_ID "ATT0022"
*HW_ATTACHMENT_NAME "RxRy|RxRy"
*HW_COUNTER_ID-0 "CUT0021"
*HW_COUNTER_ID-1 "CUT0020"
*HW_COUNTER_ID-2 ""
*HW_COUNTER_ID-3 "CSL0021"
*HW_COUNTER_ID-4 "CMC0021"
*HW_COUNTER_NAME-0 "SC-70|SC-70"
*HW_COUNTER_NAME-1 "None|None"
*HW_COUNTER_NAME-2 ""
*HW_COUNTER_NAME-3 "BBM|BBM"
*HW_COUNTER_NAME-4 "検出器モノクロメータ|Detector monochromator"
*HW_COUNTER_SELECT_NAME "SC-70|SC-70"
*HW_ECP_HV "626.0000000000"
*HW_ECP_HV_UNIT "V"
*HW_GONIOMETER_ID "GON0024"
*HW_GONIOMETER_NAME "SmartLab(In-plane)|SmartLab(In-plane)"
*HW_GONIOMETER_RADIUS-0 "90.0"
*HW_GONIOMETER_RADIUS-1 "114.0"
*HW_GONIOMETER_RADIUS-2 "190.0"
*HW_GONIOMETER_RADIUS-3 "300.0"
*HW_GONIOMETER_RADIUS-4 "187.0"
*HW_GONIOMETER_RADIUS-5 "300.0"
*HW_GONIOMETER_RADIUS-6 "113.0"
*HW_GONIOMETER_RADIUS-7 "331.0"
*HW_I_OPT_ID-0 "CBO0021"
*HW_I_OPT_ID-1 "ICR0021"
*HW_I_OPT_ID-2 "ISL0021"
*HW_I_OPT_ID-3 "ISO0021"
*HW_I_OPT_ID-4 "IAD0021"
*HW_I_OPT_ID-5 "IPR0001"
*HW_I_OPT_NAME-0 "CBOユニット|CBO unit"
*HW_I_OPT_NAME-1 "標準入射光学ユニット|Standard incident optical unit"
*HW_I_OPT_NAME-2 "標準入射スリットボックス|Standard incident slit box"
*HW_I_OPT_NAME-3 "入射平行スリット|Incident parallel slit"
*HW_I_OPT_NAME-4 "長手制限スリット|Length limiting slit"
*HW_I_OPT_NAME-5 "None|None"
*HW_R_ATTENUATER_AUTOMODE "1"
*HW_R_OPT_ID-0 "RSS0021"
*HW_R_OPT_ID-1 "RCR0022"
*HW_R_OPT_ID-2 "RSO0021"
*HW_R_OPT_ID-3 "RRS0021"
*HW_R_OPT_ID-4 "ATN0021"
*HW_R_OPT_ID-5 "RFL0021"
*HW_R_OPT_ID-6 "RAD0021"
*HW_R_OPT_NAME-0 "標準受光スリットボックス1|Standard receiving slit box # 1"
*HW_R_OPT_NAME-1 "標準受光光学ユニット1|Standard receiving unit # 1"
*HW_R_OPT_NAME-2 "標準受光光学ユニット2|Standard receiving optical unit # 2"
*HW_R_OPT_NAME-3 "標準受光スリットボックス2|Standard receiving slit box # 2"
*HW_R_OPT_NAME-4 "標準アッテネータ|Standard Attenuator"
*HW_R_OPT_NAME-5 "Cu Kβ|Cu K-beta"
*HW_R_OPT_NAME-6 "調整用受光スリット|Alignment receiving slit"
*HW_SAMPLE_HOLDER_ID "SMP0021"
*HW_SAMPLE_HOLDER_NAME "χφZクレードル|Chi phi Z cradle"
*HW_XG_CURRENT_MAX "200"
*HW_XG_CURRENT_MIN "10"
*HW_XG_CURRENT_RESOLUTION "1"
*HW_XG_CURRENT_UNIT "mA"
*HW_XG_FOCUS "0.4mm x 8mm"
*HW_XG_FOCUS_TYPE "Normal"
*HW_XG_ID "1700"
*HW_XG_NAME "9kW 開放管(45kV 200mA ID:1700)|9kW Rotating anode(45kV 200mA ID:1700)"
*HW_XG_TARGET_ATOMIC_NUMBER "29.0000000000"
*HW_XG_TARGET_NAME "Cu"
*HW_XG_TYPE "Rota"
*HW_XG_VOLTAGE_MAX "45"
*HW_XG_VOLTAGE_MIN "20"
*HW_XG_VOLTAGE_RESOLUTION "1"
*HW_XG_VOLTAGE_UNIT "kV"
*HW_XG_WATT_MAX "9"
*HW_XG_WATT_UNIT "kW"
*HW_XG_WAVE_LENGTH_ALPHA1 "1.540593"
*HW_XG_WAVE_LENGTH_ALPHA2 "1.544414"
*HW_XG_WAVE_LENGTH_BETA "1.392250"
*MEAS_COND_AXIS_NAME-0 "2θ/θ"
*MEAS_COND_AXIS_NAME-1 "2θ"
*MEAS_COND_AXIS_NAME-2 "ω"
*MEAS_COND_AXIS_NAME-3 "χ"
*MEAS_COND_AXIS_NAME-4 "φ"
*MEAS_COND_AXIS_NAME-5 "Z"
*MEAS_COND_AXIS_NAME-6 "Rx"
*MEAS_COND_AXIS_NAME-7 "Ry"
*MEAS_COND_AXIS_NAME-8 "2θ/ω"
*MEAS_COND_AXIS_NAME-9 "2θχ"
*MEAS_COND_AXIS_NAME-10 "2θχ/φ"
*MEAS_COND_AXIS_NAME-11 "α"
*MEAS_COND_AXIS_NAME-12 "β"
*MEAS_COND_AXIS_NAME-13 "θs"
*MEAS_COND_AXIS_NAME-14 "θd"
*MEAS_COND_AXIS_NAME-15 "Ts"
*MEAS_COND_AXIS_NAME-16 "CBO選択スリット"
*MEAS_COND_AXIS_NAME-17 "M"
*MEAS_COND_AXIS_NAME-18 "入射平行スリット"
*MEAS_COND_AXIS_NAME-19 "入射スリット"
*MEAS_COND_AXIS_NAME-20 ""
*MEAS_COND_AXIS_NAME-21 "Zs"
*MEAS_COND_AXIS_NAME-22 "入射光学素子"
*MEAS_COND_AXIS_NAME-23 "ωm"
*MEAS_COND_AXIS_NAME-24 "長手制限スリット"
*MEAS_COND_AXIS_NAME-25 "センタースリット"
*MEAS_COND_AXIS_NAME-26 "フィルター"
*MEAS_COND_AXIS_NAME-27 "受光スリット1"
*MEAS_COND_AXIS_NAME-28 "受光スリット2"
*MEAS_COND_AXIS_NAME-29 "受光光学素子"
*MEAS_COND_AXIS_NAME-30 "受光平行スリット"
*MEAS_COND_AXIS_NAME-31 "調整用受光スリット"
*MEAS_COND_AXIS_NAME-32 ""
*MEAS_COND_AXIS_NAME-33 ""
*MEAS_COND_AXIS_NAME-34 "Zd"
*MEAS_COND_AXIS_NAME-35 "アッテネータ"
*MEAS_COND_AXIS_NAME-36 "検出器モノクロメータ"
*MEAS_COND_AXIS_NAME-37 "モノクロメータスリット"
*MEAS_COND_AXIS_NAME-38 "2θB"
*MEAS_COND_AXIS_NAME-39 ""
*MEAS_COND_AXIS_NAME-40 ""
*MEAS_COND_AXIS_NAME-41 "プライマリビーム"
*MEAS_COND_AXIS_NAME-42 "HV"
*MEAS_COND_AXIS_NAME-43 "PHA"
*MEAS_COND_AXIS_NAME_INTERNAL-0 "TwoThetaTheta"
*MEAS_COND_AXIS_NAME_INTERNAL-1 "TwoTheta"
*MEAS_COND_AXIS_NAME_INTERNAL-2 "Omega"
*MEAS_COND_AXIS_NAME_INTERNAL-3 "Chi"
*MEAS_COND_AXIS_NAME_INTERNAL-4 "Phi"
*MEAS_COND_AXIS_NAME_INTERNAL-5 "Z"
*MEAS_COND_AXIS_NAME_INTERNAL-6 "Rx"
*MEAS_COND_AXIS_NAME_INTERNAL-7 "Ry"
*MEAS_COND_AXIS_NAME_INTERNAL-8 "TwoThetaOmega"
*MEAS_COND_AXIS_NAME_INTERNAL-9 "TwoThetaChi"
*MEAS_COND_AXIS_NAME_INTERNAL-10 "TwoThetaChiPhi"
*MEAS_COND_AXIS_NAME_INTERNAL-11 "Alpha"
*MEAS_COND_AXIS_NAME_INTERNAL-12 "Beta"
*MEAS_COND_AXIS_NAME_INTERNAL-13 "ThetaS"
*MEAS_COND_AXIS_NAME_INTERNAL-14 "ThetaD"
*MEAS_COND_AXIS_NAME_INTERNAL-15 "Ts"
*MEAS_COND_AXIS_NAME_INTERNAL-16 "CBO"
*MEAS_COND_AXIS_NAME_INTERNAL-17 "CBO-M"
*MEAS_COND_AXIS_NAME_INTERNAL-18 "IncidentSollerSlit"
*MEAS_COND_AXIS_NAME_INTERNAL-19 "IncidentSlitBox"
*MEAS_COND_AXIS_NAME_INTERNAL-20 "IncidentSlitBox-_Axis"
*MEAS_COND_AXIS_NAME_INTERNAL-21 "Zs"
*MEAS_COND_AXIS_NAME_INTERNAL-22 "IncidentMonochromator"
*MEAS_COND_AXIS_NAME_INTERNAL-23 "IncidentMonochromator-OmegaM"
*MEAS_COND_AXIS_NAME_INTERNAL-24 "IncidentAxdSlit"
*MEAS_COND_AXIS_NAME_INTERNAL-25 "CenterSlit"
*MEAS_COND_AXIS_NAME_INTERNAL-26 "Filter"
*MEAS_COND_AXIS_NAME_INTERNAL-27 "ReceivingSlitBox1"
*MEAS_COND_AXIS_NAME_INTERNAL-28 "ReceivingSlitBox2"
*MEAS_COND_AXIS_NAME_INTERNAL-29 "ReceivingOptics"
*MEAS_COND_AXIS_NAME_INTERNAL-30 "ReceivingSollerSlit"
*MEAS_COND_AXIS_NAME_INTERNAL-31 "ReceivingAxdSlit"
*MEAS_COND_AXIS_NAME_INTERNAL-32 "ReceivingSlitBox1-_Axis"
*MEAS_COND_AXIS_NAME_INTERNAL-33 "ReceivingSlitBox2-_Axis"
*MEAS_COND_AXIS_NAME_INTERNAL-34 "ReceivingSlitBox2-Zd"
*MEAS_COND_AXIS_NAME_INTERNAL-35 "Attenuator"
*MEAS_COND_AXIS_NAME_INTERNAL-36 "CounterMonochromator"
*MEAS_COND_AXIS_NAME_INTERNAL-37 "CounterSlit"
*MEAS_COND_AXIS_NAME_INTERNAL-38 "TwoThetaB"
*MEAS_COND_AXIS_NAME_INTERNAL-39 "AlphaR"
*MEAS_COND_AXIS_NAME_INTERNAL-40 "BetaR"
*MEAS_COND_AXIS_NAME_INTERNAL-41 "IncidentPrimary"
*MEAS_COND_AXIS_NAME_INTERNAL-42 "HV"
*MEAS_COND_AXIS_NAME_INTERNAL-43 "PHA"
*MEAS_COND_AXIS_NAME_MAGICNO-0 "83951616.0000000000"
*MEAS_COND_AXIS_NAME_MAGICNO-1 "268632064.0000000000"
*MEAS_COND_AXIS_NAME_MAGICNO-2 "268500992.0000000000"
*MEAS_COND_AXIS_NAME_MAGICNO-3 "268500992.0000000000"
*MEAS_COND_AXIS_NAME_MAGICNO-4 "268500992.0000000000"
*MEAS_COND_AXIS_NAME_MAGICNO-5 "285278208.0000000000"
*MEAS_COND_AXIS_NAME_MAGICNO-6 "285278208.0000000000"
*MEAS_COND_AXIS_NAME_MAGICNO-7 "285278208.0000000000"
*MEAS_COND_AXIS_NAME_MAGICNO-8 "83951616.0000000000"
*MEAS_COND_AXIS_NAME_MAGICNO-9 "268632064.0000000000"
*MEAS_COND_AXIS_NAME_MAGICNO-10 "83951616.0000000000"
*MEAS_COND_AXIS_NAME_MAGICNO-11 "17039360.0000000000"
*MEAS_COND_AXIS_NAME_MAGICNO-12 "17039360.0000000000"
*MEAS_COND_AXIS_NAME_MAGICNO-13 "131072.0000000000"
*MEAS_COND_AXIS_NAME_MAGICNO-14 "131072.0000000000"
*MEAS_COND_AXIS_NAME_MAGICNO-15 "318898176.0000000000"
*MEAS_COND_AXIS_NAME_MAGICNO-16 "20971521.0000000000"
*MEAS_COND_AXIS_NAME_MAGICNO-17 "285343744.0000000000"
*MEAS_COND_AXIS_NAME_MAGICNO-18 "20971521.0000000000"
*MEAS_COND_AXIS_NAME_MAGICNO-19 "22020097.0000000000"
*MEAS_COND_AXIS_NAME_MAGICNO-20 "25165824.0000000000"
*MEAS_COND_AXIS_NAME_MAGICNO-21 "318898176.0000000000"
*MEAS_COND_AXIS_NAME_MAGICNO-22 "20971521.0000000000"
*MEAS_COND_AXIS_NAME_MAGICNO-23 "285343744.0000000000"
*MEAS_COND_AXIS_NAME_MAGICNO-24 "20971521.0000000000"
*MEAS_COND_AXIS_NAME_MAGICNO-25 "20971521.0000000000"
*MEAS_COND_AXIS_NAME_MAGICNO-26 "20971521.0000000000"
*MEAS_COND_AXIS_NAME_MAGICNO-27 "23068673.0000000000"
*MEAS_COND_AXIS_NAME_MAGICNO-28 "23068673.0000000000"
*MEAS_COND_AXIS_NAME_MAGICNO-29 "20971521.0000000000"
*MEAS_COND_AXIS_NAME_MAGICNO-30 "20971521.0000000000"
*MEAS_COND_AXIS_NAME_MAGICNO-31 "20971521.0000000000"
*MEAS_COND_AXIS_NAME_MAGICNO-32 "25165824.0000000000"
*MEAS_COND_AXIS_NAME_MAGICNO-33 "25165824.0000000000"
*MEAS_COND_AXIS_NAME_MAGICNO-34 "285343744.0000000000"
*MEAS_COND_AXIS_NAME_MAGICNO-35 "17301505.0000000000"
*MEAS_COND_AXIS_NAME_MAGICNO-36 "20971521.0000000000"
*MEAS_COND_AXIS_NAME_MAGICNO-37 "20971521.0000000000"
*MEAS_COND_AXIS_NAME_MAGICNO-38 "17039360.0000000000"
*MEAS_COND_AXIS_NAME_MAGICNO-39 "8388608.0000000000"
*MEAS_COND_AXIS_NAME_MAGICNO-40 "8388608.0000000000"
*MEAS_COND_AXIS_NAME_MAGICNO-41 "20971521.0000000000"
*MEAS_COND_AXIS_NAME_MAGICNO-42 "0.0000000000"
*MEAS_COND_AXIS_NAME_MAGICNO-43 "0.0000000000"
*MEAS_COND_AXIS_OFFSET-0 "-"
*MEAS_COND_AXIS_OFFSET-1 "1.2881000000"
*MEAS_COND_AXIS_OFFSET-2 "1.3524000000"
*MEAS_COND_AXIS_OFFSET-3 "0.0000000000"
*MEAS_COND_AXIS_OFFSET-4 "0.0000000000"
*MEAS_COND_AXIS_OFFSET-5 "-"
*MEAS_COND_AXIS_OFFSET-6 "-"
*MEAS_COND_AXIS_OFFSET-7 "-"
*MEAS_COND_AXIS_OFFSET-8 "-"
*MEAS_COND_AXIS_OFFSET-9 "0.0000000000"
*MEAS_COND_AXIS_OFFSET-10 "-"
*MEAS_COND_AXIS_OFFSET-11 "-"
*MEAS_COND_AXIS_OFFSET-12 "-"
*MEAS_COND_AXIS_OFFSET-13 "1.3524000000"
*MEAS_COND_AXIS_OFFSET-14 "-0.0643000000"
*MEAS_COND_AXIS_OFFSET-15 "-"
*MEAS_COND_AXIS_OFFSET-16 "-"
*MEAS_COND_AXIS_OFFSET-17 "-"
*MEAS_COND_AXIS_OFFSET-18 "-"
*MEAS_COND_AXIS_OFFSET-19 "-"
*MEAS_COND_AXIS_OFFSET-20 "-"
*MEAS_COND_AXIS_OFFSET-21 "-"
*MEAS_COND_AXIS_OFFSET-22 "-"
*MEAS_COND_AXIS_OFFSET-23 "-"
*MEAS_COND_AXIS_OFFSET-24 "-"
*MEAS_COND_AXIS_OFFSET-25 "-"
*MEAS_COND_AXIS_OFFSET-26 "-"
*MEAS_COND_AXIS_OFFSET-27 "-"
*MEAS_COND_AXIS_OFFSET-28 "-"
*MEAS_COND_AXIS_OFFSET-29 "-"
*MEAS_COND_AXIS_OFFSET-30 "-"
*MEAS_COND_AXIS_OFFSET-31 "-"
*MEAS_COND_AXIS_OFFSET-32 "-"
*MEAS_COND_AXIS_OFFSET-33 "-"
*MEAS_COND_AXIS_OFFSET-34 "-"
*MEAS_COND_AXIS_OFFSET-35 "-"
*MEAS_COND_AXIS_OFFSET-36 "-"
*MEAS_COND_AXIS_OFFSET-37 "-"
*MEAS_COND_AXIS_OFFSET-38 "-"
*MEAS_COND_AXIS_OFFSET-39 "0.0000000000"
*MEAS_COND_AXIS_OFFSET-40 "0.0000000000"
*MEAS_COND_AXIS_OFFSET-41 "-"
*MEAS_COND_AXIS_OFFSET-42 "-"
*MEAS_COND_AXIS_OFFSET-43 "-"
*MEAS_COND_AXIS_POSITION-0 "-0.0020000000"
*MEAS_COND_AXIS_POSITION-1 "-0.0020000000"
*MEAS_COND_AXIS_POSITION-2 "-0.0010000000"
*MEAS_COND_AXIS_POSITION-3 "-0.7120000000"
*MEAS_COND_AXIS_POSITION-4 "0.0000000000"
*MEAS_COND_AXIS_POSITION-5 "-0.3301000000"
*MEAS_COND_AXIS_POSITION-6 "0.0000000000"
*MEAS_COND_AXIS_POSITION-7 "0.0000000000"
*MEAS_COND_AXIS_POSITION-8 "-0.0020000000"
*MEAS_COND_AXIS_POSITION-9 "0.0000000000"
*MEAS_COND_AXIS_POSITION-10 "0.0000000000"
*MEAS_COND_AXIS_POSITION-11 "-89.9800000000"
*MEAS_COND_AXIS_POSITION-12 "0.0000000000"
*MEAS_COND_AXIS_POSITION-13 "-0.0010000000"
*MEAS_COND_AXIS_POSITION-14 "-0.0010000000"
*MEAS_COND_AXIS_POSITION-15 "-6.2162500000"
*MEAS_COND_AXIS_POSITION-16 "PB"
*MEAS_COND_AXIS_POSITION-17 "0.0000000000"
*MEAS_COND_AXIS_POSITION-18 "Soller_slit_open_s"
*MEAS_COND_AXIS_POSITION-19 "0.100mm"
*MEAS_COND_AXIS_POSITION-20 "0.1000000000"
*MEAS_COND_AXIS_POSITION-21 "-1.7100000000"
*MEAS_COND_AXIS_POSITION-22 "Ge(220)x2"
*MEAS_COND_AXIS_POSITION-23 "0.0000000000"
*MEAS_COND_AXIS_POSITION-24 "10.0mm"
*MEAS_COND_AXIS_POSITION-25 "None"
*MEAS_COND_AXIS_POSITION-26 "None"
*MEAS_COND_AXIS_POSITION-27 "0.200mm"
*MEAS_COND_AXIS_POSITION-28 "0.200mm"
*MEAS_COND_AXIS_POSITION-29 "PSA_open"
*MEAS_COND_AXIS_POSITION-30 "Soller_slit_5.0deg"
*MEAS_COND_AXIS_POSITION-31 "None"
*MEAS_COND_AXIS_POSITION-32 "0.2000000000"
*MEAS_COND_AXIS_POSITION-33 "0.2000000000"
*MEAS_COND_AXIS_POSITION-34 "0.2290600000"
*MEAS_COND_AXIS_POSITION-35 "1/10000"
*MEAS_COND_AXIS_POSITION-36 "None"
*MEAS_COND_AXIS_POSITION-37 "None"
*MEAS_COND_AXIS_POSITION-38 "0.0020000000"
*MEAS_COND_AXIS_POSITION-39 "0.0000000000"
*MEAS_COND_AXIS_POSITION-40 "0.0000000000"
*MEAS_COND_AXIS_POSITION-41 "None"
*MEAS_COND_AXIS_POSITION-42 "626.0000000000"
*MEAS_COND_AXIS_POSITION-43 "603.7500000000"
*MEAS_COND_AXIS_UNIT-0 "deg"
*MEAS_COND_AXIS_UNIT-1 "deg"
*MEAS_COND_AXIS_UNIT-2 "deg"
*MEAS_COND_AXIS_UNIT-3 "deg"
*MEAS_COND_AXIS_UNIT-4 "deg"
*MEAS_COND_AXIS_UNIT-5 "mm"
*MEAS_COND_AXIS_UNIT-6 "deg"
*MEAS_COND_AXIS_UNIT-7 "deg"
*MEAS_COND_AXIS_UNIT-8 "deg"
*MEAS_COND_AXIS_UNIT-9 "deg"
*MEAS_COND_AXIS_UNIT-10 "deg"
*MEAS_COND_AXIS_UNIT-11 "deg"
*MEAS_COND_AXIS_UNIT-12 "deg"
*MEAS_COND_AXIS_UNIT-13 "deg"
*MEAS_COND_AXIS_UNIT-14 "deg"
*MEAS_COND_AXIS_UNIT-15 "mm"
*MEAS_COND_AXIS_UNIT-16 ""
*MEAS_COND_AXIS_UNIT-17 "pulse"
*MEAS_COND_AXIS_UNIT-18 ""
*MEAS_COND_AXIS_UNIT-19 ""
*MEAS_COND_AXIS_UNIT-20 "mm"
*MEAS_COND_AXIS_UNIT-21 "mm"
*MEAS_COND_AXIS_UNIT-22 ""
*MEAS_COND_AXIS_UNIT-23 "pulse"
*MEAS_COND_AXIS_UNIT-24 ""
*MEAS_COND_AXIS_UNIT-25 ""
*MEAS_COND_AXIS_UNIT-26 ""
*MEAS_COND_AXIS_UNIT-27 ""
*MEAS_COND_AXIS_UNIT-28 ""
*MEAS_COND_AXIS_UNIT-29 ""
*MEAS_COND_AXIS_UNIT-30 ""
*MEAS_COND_AXIS_UNIT-31 ""
*MEAS_COND_AXIS_UNIT-32 "mm"
*MEAS_COND_AXIS_UNIT-33 "mm"
*MEAS_COND_AXIS_UNIT-34 "mm"
*MEAS_COND_AXIS_UNIT-35 ""
*MEAS_COND_AXIS_UNIT-36 ""
*MEAS_COND_AXIS_UNIT-37 ""
*MEAS_COND_AXIS_UNIT-38 "deg"
*MEAS_COND_AXIS_UNIT-39 "deg"
*MEAS_COND_AXIS_UNIT-40 "deg"
*MEAS_COND_AXIS_UNIT-41 ""
*MEAS_COND_AXIS_UNIT-42 "V"
*MEAS_COND_AXIS_UNIT-43 "mV"
*MEAS_COND_COUNTER_CNTLOSS_CORR "1.0000000000"
*MEAS_COND_COUNTER_PHABASE "603.7500000000"
*MEAS_COND_COUNTER_PHAWINDOW "855.0000000000"
*MEAS_COND_COUNTER_PHA_UNIT "mV"
*MEAS_COND_COUNTER_TAUDIFF "0.1777010000"
*MEAS_COND_COUNTER_TAUINT "0.6912320000"
*MEAS_COND_IRRADIATION_MODE "OFF"
*MEAS_COND_IRRADIATION_WIDTH ""
*MEAS_COND_OPT_ATTR "高分解能平行ビームGe(220)x2/受光スリット"
*MEAS_COND_OPT_NAME "@高分解能PB-Ge(220)x2"
*MEAS_COND_UNSYMMETRIC_MODE "OFF"
*MEAS_COND_XG_CURRENT "200.0000000000"
*MEAS_COND_XG_VOLTAGE "45.0000000000"
*MEAS_COND_XG_WAVE_TYPE "Ka1"
*MEAS_DATA_COUNT "1501.0000000000"
*MEAS_SCAN_AXIS_X "2θ/ω"
*MEAS_SCAN_AXIS_X_INTERNAL "TwoThetaOmega"
*MEAS_SCAN_END_TIME "03/31/21 15:31:40"
*MEAS_SCAN_MODE "CONTINUOUS"
*MEAS_SCAN_MONITOR "0"
*MEAS_SCAN_RESOLUTION_X "0.0002"
*MEAS_SCAN_SPEED "0.400000"
*MEAS_SCAN_SPEED_UNIT "deg/min"
*MEAS_SCAN_SPEED_USER "0.4000"
*MEAS_SCAN_START "0.0000000000"
*MEAS_SCAN_START_TIME "03/31/21 15:16:04"
*MEAS_SCAN_STEP "0.0040000000"
*MEAS_SCAN_STOP "6.0000000000"
*MEAS_SCAN_UNIT_X "deg"
*MEAS_SCAN_UNIT_Y "counts"
*RAS_HEADER_END
*RAS_INT_START
0.0000 26068.0000 837.5800
0.0080 25666.0000 837.5800
0.0160 21656.0000 837.5800
0.0240 12552.0000 837.5800
0.0320 4297.0000 837.5800
0.0400 18178.0000 53.5042
0.0480 8635.0000 53.5042
0.0560 9630.0000 53.5042
0.0640 16046.0000 53.5042
0.0720 26310.0000 53.5042
0.0800 39690.0000 53.5042
0.0880 54707.0000 53.5042
0.0960 70196.0000 53.5042
0.1040 85229.0000 53.5042
0.1120 96034.0000 53.5042
0.1200 105454.0000 53.5042
0.1280 111307.0000 53.5042
0.1360 116966.0078 53.5042
0.1440 120999.0000 53.5042
0.1520 126743.0000 53.5042
0.1600 133767.0000 53.5042
0.1680 139726.0000 53.5042
0.1760 141233.0000 53.5042
0.1840 142192.0000 53.5042
0.1920 140577.0000 53.5042
0.2000 139134.0000 53.5042
0.2080 140381.0000 53.5042
0.2160 143659.0000 53.5042
0.2240 149889.0000 53.5042
0.2320 159947.0000 53.5042
0.2400 166858.0000 53.5042
0.2480 177214.0000 53.5042
0.2560 186859.0000 53.5042
0.2640 196516.0000 53.5042
0.2720 206587.0000 53.5042
0.2800 215714.0000 53.5042
0.2880 226272.0000 53.5042
0.2960 237279.0000 53.5042
0.3040 15878.0000 837.5800
0.3120 16352.0000 837.5800
0.3200 16879.0000 837.5800
0.3280 17627.0000 837.5800
0.3360 18185.0000 837.5800
0.3440 18934.0000 837.5800
0.3520 19583.0000 837.5800
0.3600 20125.0000 837.5800
0.3680 21030.9980 837.5800
0.3760 21360.0000 837.5800
0.3840 21678.9980 837.5800
0.3920 22229.0000 837.5800
0.4000 22978.9980 837.5800
0.4080 23263.0000 837.5800
0.4160 23811.0000 837.5800
0.4240 24342.0000 837.5800
0.4320 24802.0020 837.5800
0.4400 25019.0000 837.5800
0.4480 25563.0000 837.5800
0.4560 25600.0000 837.5800
0.4640 26125.0000 837.5800
0.4720 26621.0020 837.5800
0.4800 26978.9980 837.5800
0.4880 26867.0000 837.5800
0.4960 26924.0000 837.5800
0.5040 27468.0000 837.5800
0.5120 27777.0000 837.5800
0.5200 27484.0000 837.5800
0.5280 28009.0000 837.5800
0.5360 28118.0000 837.5800
0.5440 28105.0000 837.5800
0.5520 28153.0000 837.5800
0.5600 27739.0000 837.5800
0.5680 28115.0000 837.5800
0.5760 27807.0020 837.5800
0.5840 27705.0000 837.5800
0.5920 27596.0000 837.5800
0.6000 27368.0000 837.5800
0.6080 26811.9980 837.5800
0.6160 26806.0000 837.5800
0.6240 26397.0000 837.5800
0.6320 25752.0000 837.5800
0.6400 25716.9980 837.5800
0.6480 25214.0000 837.5800
0.6560 24729.0000 837.5800
0.6640 23949.0000 837.5800
0.6720 23533.0000 837.5800
0.6800 22908.0000 837.5800
0.6880 22039.0000 837.5800
0.6960 21484.0000 837.5800
0.7040 20684.0000 837.5800
0.7120 19789.0000 837.5800
0.7200 18691.0000 837.5800
0.7280 17623.0000 837.5800
0.7360 16460.0000 837.5800
0.7440 15472.0000 837.5800
0.7520 14222.0000 837.5800
0.7600 12945.0000 837.5800
0.7680 11979.0000 837.5800
0.7760 10874.9990 837.5800
0.7840 9895.0000 837.5800
0.7920 9048.0000 837.5800
0.8000 7937.0000 837.5800
0.8080 7390.0000 837.5800
0.8160 6552.0000 837.5800
0.8240 5962.0000 837.5800
0.8320 5477.0000 837.5800
0.8400 5006.0000 837.5800
0.8480 4552.0000 837.5800
0.8560 4193.0000 837.5800
0.8640 3809.0000 837.5800
0.8720 3540.0000 837.5800
0.8800 3245.0000 837.5800
0.8880 46665.0000 53.5042
0.8960 42769.0039 53.5042
0.9040 39549.9961 53.5042
0.9120 36923.0000 53.5042
0.9200 33970.0000 53.5042
0.9280 32084.0000 53.5042
0.9360 29675.0000 53.5042
0.9440 27578.0000 53.5042
0.9520 25644.0000 53.5042
0.9600 24230.0000 53.5042
0.9680 22571.0000 53.5042
0.9760 21202.9980 53.5042
0.9840 19400.0000 53.5042
0.9920 18795.0000 53.5042
1.0000 17394.0000 53.5042
1.0080 16589.0000 53.5042
1.0160 15467.0000 53.5042
1.0240 14637.0000 53.5042
1.0320 13649.0000 53.5042
1.0400 13062.0000 53.5042
1.0480 12017.0010 53.5042
1.0560 11452.0010 53.5042
1.0640 10765.0000 53.5042
1.0720 10207.0000 53.5042
1.0800 9876.0000 53.5042
1.0880 9351.0000 53.5042
1.0960 8745.0000 53.5042
1.1040 8240.0000 53.5042
1.1120 7733.9995 53.5042
1.1200 7196.0000 53.5042
1.1280 6876.0000 53.5042
1.1360 6578.0000 53.5042
1.1440 6270.0000 53.5042
1.1520 6087.0000 53.5042
1.1600 5864.0000 53.5042
1.1680 5470.0000 53.5042
1.1760 5117.0000 53.5042
1.1840 4770.0000 53.5042
1.1920 4471.0000 53.5042
1.2000 4286.0000 53.5042
1.2080 4175.0000 53.5042
1.2160 3950.0000 53.5042
1.2240 3988.0000 53.5042
1.2320 3746.0000 53.5042
1.2400 3464.0000 53.5042
1.2480 3278.0000 53.5042
1.2560 2971.0000 53.5042
1.2640 2807.0002 53.5042
1.2720 2734.0000 53.5042
1.2800 2670.0000 53.5042
1.2880 2610.0002 53.5042
1.2960 2568.0000 53.5042
1.3040 2420.0000 53.5042
1.3120 2297.0000 53.5042
1.3200 2115.0000 53.5042
1.3280 1912.9999 53.5042
1.3360 1860.9999 53.5042
1.3440 1722.0000 53.5042
1.3520 1723.0000 53.5042
1.3600 1776.0000 53.5042
1.3680 1770.0001 53.5042
1.3760 1749.0000 53.5042
1.3840 1588.0000 53.5042
1.3920 79250.0000 1.0000
1.4000 71979.0000 1.0000
1.4080 65915.0000 1.0000
1.4160 60949.0000 1.0000
1.4240 60223.0000 1.0000
1.4320 60884.0000 1.0000
1.4400 61642.0000 1.0000
1.4480 61829.0000 1.0000
1.4560 59734.0000 1.0000
1.4640 55565.0000 1.0000
1.4720 50104.0000 1.0000
1.4800 44325.0000 1.0000
1.4880 40416.0000 1.0000
1.4960 38459.0000 1.0000
1.5040 37723.0000 1.0000
1.5120 38976.0000 1.0000
1.5200 41011.0000 1.0000
1.5280 41421.0000 1.0000
1.5360 39932.0000 1.0000
1.5440 36174.0000 1.0000
1.5520 32386.0000 1.0000
1.5600 28481.0000 1.0000
1.5680 25457.0000 1.0000
1.5760 23936.0000 1.0000
1.5840 24417.0000 1.0000
1.5920 25434.0000 1.0000
1.6000 26766.0000 1.0000
1.6080 27337.0000 1.0000
1.6160 26601.0000 1.0000
1.6240 24525.0000 1.0000
1.6320 21429.0000 1.0000
1.6400 18282.0000 1.0000
1.6480 16060.0000 1.0000
1.6560 14851.0000 1.0000
1.6640 15105.0000 1.0000
1.6720 16131.0000 1.0000
1.6800 17396.0000 1.0000
1.6880 18066.0000 1.0000
1.6960 18008.0000 1.0000
1.7040 16469.0000 1.0000
1.7120 14306.0000 1.0000
1.7200 12015.0000 1.0000
1.7280 10084.0000 1.0000
1.7360 9128.0000 1.0000
1.7440 9172.0000 1.0000
1.7520 10123.0000 1.0000
1.7600 11069.0000 1.0000
1.7680 11900.0000 1.0000
1.7760 12040.0000 1.0000
1.7840 11285.0000 1.0000
1.7920 10057.0000 1.0000
1.8000 8086.0000 1.0000
1.8080 6697.0000 1.0000
1.8160 5679.0000 1.0000
1.8240 5532.0000 1.0000
1.8320 6091.0000 1.0000
1.8400 7095.0000 1.0000
1.8480 7683.0000 1.0000
1.8560 8185.0000 1.0000
1.8640 7865.0000 1.0000
1.8720 7095.0000 1.0000
1.8800 5786.0000 1.0000
1.8880 4434.0000 1.0000
1.8960 3700.0000 1.0000
1.9040 3396.0000 1.0000
1.9120 3687.0000 1.0000
1.9200 4308.0000 1.0000
1.9280 4911.0000 1.0000
1.9360 5586.0000 1.0000
1.9440 5500.0000 1.0000
1.9520 4962.0000 1.0000
1.9600 4193.0000 1.0000
1.9680 3244.0000 1.0000
1.9760 2429.0000 1.0000
1.9840 2139.0000 1.0000
1.9920 2165.0000 1.0000
2.0000 2565.0000 1.0000
2.0080 3130.0000 1.0000
2.0160 3641.0000 1.0000
2.0240 3834.0000 1.0000
2.0320 3618.0000 1.0000
2.0400 3128.0000 1.0000
2.0480 2472.0000 1.0000
2.0560 1821.0000 1.0000
2.0640 1466.0000 1.0000
2.0720 1324.0000 1.0000
2.0800 1531.0000 1.0000
2.0880 1991.0000 1.0000
2.0960 2340.0000 1.0000
2.1040 2683.0000 1.0000
2.1120 2601.0000 1.0000
2.1200 2398.0000 1.0000
2.1280 1979.0000 1.0000
2.1360 1394.0000 1.0000
2.1440 1103.0000 1.0000
2.1520 848.0000 1.0000
2.1600 909.0000 1.0000
2.1680 1173.0000 1.0000
2.1760 1540.0000 1.0000
2.1840 1813.0000 1.0000
2.1920 2053.0000 1.0000
2.2000 1840.0000 1.0000
2.2080 1612.0000 1.0000
2.2160 1163.0000 1.0000
2.2240 910.0000 1.0000
2.2320 703.0000 1.0000
2.2400 631.0000 1.0000
2.2480 782.0000 1.0000
2.2560 1107.0000 1.0000
2.2640 1372.0000 1.0000
2.2720 1517.0000 1.0000
2.2800 1509.0000 1.0000
2.2880 1450.0000 1.0000
2.2960 1127.0000 1.0000
2.3040 839.0000 1.0000
2.3120 523.0000 1.0000
2.3200 531.0000 1.0000
2.3280 530.0000 1.0000
2.3360 776.0000 1.0000
2.3440 1035.0000 1.0000
2.3520 1226.0000 1.0000
2.3600 1317.0000 1.0000
2.3680 1221.0000 1.0000
2.3760 1070.0000 1.0000
2.3840 845.0000 1.0000
2.3920 616.0000 1.0000
2.4000 457.0000 1.0000
2.4080 407.0000 1.0000
2.4160 573.0000 1.0000
2.4240 799.0000 1.0000
2.4320 1003.0000 1.0000
2.4400 1106.0000 1.0000
2.4480 1121.0000 1.0000
2.4560 1086.0000 1.0000
2.4640 886.0000 1.0000
2.4720 643.0000 1.0000
2.4800 452.0000 1.0000
2.4880 387.0000 1.0000
2.4960 467.0000 1.0000
2.5040 587.0000 1.0000
2.5120 789.0000 1.0000
2.5200 1006.0000 1.0000
2.5280 1106.0000 1.0000
2.5360 1033.0000 1.0000
2.5440 998.0000 1.0000
2.5520 744.0000 1.0000
2.5600 544.0000 1.0000
2.5680 421.0000 1.0000
2.5760 360.0000 1.0000
2.5840 491.0000 1.0000
2.5920 654.0000 1.0000
2.6000 820.0000 1.0000
2.6080 970.0000 1.0000
2.6160 1044.0000 1.0000
2.6240 979.0000 1.0000
2.6320 907.0000 1.0000
2.6400 725.0000 1.0000
2.6480 470.0000 1.0000
2.6560 419.0000 1.0000
2.6640 355.0000 1.0000
2.6720 480.0000 1.0000
2.6800 667.0000 1.0000
2.6880 843.0000 1.0000
2.6960 1036.0000 1.0000
2.7040 1011.0000 1.0000
2.7120 1031.0000 1.0000
2.7200 874.0000 1.0000
2.7280 649.0000 1.0000
2.7360 509.0000 1.0000
2.7440 357.0000 1.0000
2.7520 385.0000 1.0000
2.7600 509.0000 1.0000
2.7680 698.0000 1.0000
2.7760 805.0000 1.0000
2.7840 986.0000 1.0000
2.7920 1046.0000 1.0000
2.8000 946.0000 1.0000
2.8080 882.0000 1.0000
2.8160 679.0000 1.0000
2.8240 491.0000 1.0000
2.8320 405.0000 1.0000
2.8400 408.0000 1.0000
2.8480 499.0000 1.0000
2.8560 669.0000 1.0000
2.8640 876.0000 1.0000
2.8720 999.0000 1.0000
2.8800 997.0000 1.0000
2.8880 952.0000 1.0000
2.8960 862.0000 1.0000
2.9040 656.0000 1.0000
2.9120 512.0000 1.0000
2.9200 421.0000 1.0000
2.9280 417.0000 1.0000
2.9360 505.0000 1.0000
2.9440 652.0000 1.0000
2.9520 818.0000 1.0000
2.9600 960.0000 1.0000
2.9680 959.0000 1.0000
2.9760 935.0000 1.0000
2.9840 829.0000 1.0000
2.9920 669.0000 1.0000
3.0000 509.0000 1.0000
3.0080 423.0000 1.0000
3.0160 425.0000 1.0000
3.0240 491.0000 1.0000
3.0320 638.0000 1.0000
3.0400 816.0000 1.0000
3.0480 943.0000 1.0000
3.0560 965.0000 1.0000
3.0640 912.0000 1.0000
3.0720 826.0000 1.0000
3.0800 644.0000 1.0000
3.0880 508.0000 1.0000
3.0960 407.0000 1.0000
3.1040 432.0000 1.0000
3.1120 474.0000 1.0000
3.1200 593.0000 1.0000
3.1280 748.0000 1.0000
3.1360 871.0000 1.0000
3.1440 953.0000 1.0000
3.1520 928.0000 1.0000
3.1600 749.0000 1.0000
3.1680 668.0000 1.0000
3.1760 516.0000 1.0000
3.1840 440.0000 1.0000
3.1920 408.0000 1.0000
3.2000 483.0000 1.0000
3.2080 566.0000 1.0000
3.2160 671.0000 1.0000
3.2240 812.0000 1.0000
3.2320 930.0000 1.0000
3.2400 871.0000 1.0000
3.2480 745.0000 1.0000
3.2560 607.0000 1.0000
3.2640 482.0000 1.0000
3.2720 438.0000 1.0000
3.2800 357.0000 1.0000
3.2880 397.0000 1.0000
3.2960 519.0000 1.0000
3.3040 667.0000 1.0000
3.3120 727.0000 1.0000
3.3200 811.0000 1.0000
3.3280 798.0000 1.0000
3.3360 772.0000 1.0000
3.3440 592.0000 1.0000
3.3520 512.0000 1.0000
3.3600 398.0000 1.0000
3.3680 425.0000 1.0000
3.3760 380.0000 1.0000
3.3840 477.0000 1.0000
3.3920 577.0000 1.0000
3.4000 703.0000 1.0000
3.4080 775.0000 1.0000
3.4160 780.0000 1.0000
3.4240 730.0000 1.0000
3.4320 622.0000 1.0000
3.4400 478.0000 1.0000
3.4480 388.0000 1.0000
3.4560 356.0000 1.0000
3.4640 358.0000 1.0000
3.4720 400.0000 1.0000
3.4800 546.0000 1.0000
3.4880 613.0000 1.0000
3.4960 691.0000 1.0000
3.5040 672.0000 1.0000
3.5120 700.0000 1.0000
3.5200 616.0000 1.0000
3.5280 482.0000 1.0000
3.5360 381.0000 1.0000
3.5440 298.0000 1.0000
3.5520 355.0000 1.0000
3.5600 388.0000 1.0000
3.5680 447.0000 1.0000
3.5760 566.0000 1.0000
3.5840 563.0000 1.0000
3.5920 665.0000 1.0000
3.6000 636.0000 1.0000
3.6080 576.0000 1.0000
3.6160 462.0000 1.0000
3.6240 416.0000 1.0000
3.6320 317.0000 1.0000
3.6400 302.0000 1.0000
3.6480 333.0000 1.0000
3.6560 396.0000 1.0000
3.6640 487.0000 1.0000
3.6720 532.0000 1.0000
3.6800 582.0000 1.0000
3.6880 567.0000 1.0000
3.6960 504.0000 1.0000
3.7040 442.0000 1.0000
3.7120 366.0000 1.0000
3.7200 293.0000 1.0000
3.7280 299.0000 1.0000
3.7360 333.0000 1.0000
3.7440 378.0000 1.0000
3.7520 434.0000 1.0000
3.7600 501.0000 1.0000
3.7680 520.0000 1.0000
3.7760 520.0000 1.0000
3.7840 474.0000 1.0000
3.7920 436.0000 1.0000
3.8000 349.0000 1.0000
3.8080 279.0000 1.0000
3.8160 281.0000 1.0000
3.8240 279.0000 1.0000
3.8320 282.0000 1.0000
3.8400 357.0000 1.0000
3.8480 443.0000 1.0000
3.8560 443.0000 1.0000
3.8640 476.0000 1.0000
3.8720 463.0000 1.0000
3.8800 387.0000 1.0000
3.8880 346.0000 1.0000
3.8960 308.0000 1.0000
3.9040 275.0000 1.0000
3.9120 240.0000 1.0000
3.9200 269.0000 1.0000
3.9280 327.0000 1.0000
3.9360 401.0000 1.0000
3.9440 442.0000 1.0000
3.9520 405.0000 1.0000
3.9600 413.0000 1.0000
3.9680 362.0000 1.0000
3.9760 323.0000 1.0000
3.9840 255.0000 1.0000
3.9920 228.0000 1.0000
4.0000 192.0000 1.0000
4.0080 234.0000 1.0000
4.0160 291.0000 1.0000
4.0240 314.0000 1.0000
4.0320 383.0000 1.0000
4.0400 367.0000 1.0000
4.0480 396.0000 1.0000
4.0560 307.0000 1.0000
4.0640 333.0000 1.0000
4.0720 272.0000 1.0000
4.0800 213.0000 1.0000
4.0880 222.0000 1.0000
4.0960 196.0000 1.0000
4.1040 243.0000 1.0000
4.1120 258.0000 1.0000
4.1200 316.0000 1.0000
4.1280 356.0000 1.0000
4.1360 354.0000 1.0000
4.1440 342.0000 1.0000
4.1520 285.0000 1.0000
4.1600 270.0000 1.0000
4.1680 185.0000 1.0000
4.1760 190.0000 1.0000
4.1840 183.0000 1.0000
4.1920 205.0000 1.0000
4.2000 240.0000 1.0000
4.2080 257.0000 1.0000
4.2160 318.0000 1.0000
4.2240 308.0000 1.0000
4.2320 259.0000 1.0000
4.2400 256.0000 1.0000
4.2480 224.0000 1.0000
4.2560 188.0000 1.0000
4.2640 188.0000 1.0000
4.2720 142.0000 1.0000
4.2800 165.0000 1.0000
4.2880 210.0000 1.0000
4.2960 208.0000 1.0000
4.3040 272.0000 1.0000
4.3120 262.0000 1.0000
4.3200 273.0000 1.0000
4.3280 250.0000 1.0000
4.3360 189.0000 1.0000
4.3440 183.0000 1.0000
4.3520 149.0000 1.0000
4.3600 140.0000 1.0000
4.3680 123.0000 1.0000
4.3760 150.0000 1.0000
4.3840 191.0000 1.0000
4.3920 192.0000 1.0000
4.4000 216.0000 1.0000
4.4080 261.0000 1.0000
4.4160 213.0000 1.0000
4.4240 191.0000 1.0000
4.4320 169.0000 1.0000
4.4400 134.0000 1.0000
4.4480 130.0000 1.0000
4.4560 114.0000 1.0000
4.4640 130.0000 1.0000
4.4720 163.0000 1.0000
4.4800 183.0000 1.0000
4.4880 198.0000 1.0000
4.4960 195.0000 1.0000
4.5040 194.0000 1.0000
4.5120 187.0000 1.0000
4.5200 171.0000 1.0000
4.5280 121.0000 1.0000
4.5360 117.0000 1.0000
4.5440 95.0000 1.0000
4.5520 124.0000 1.0000
4.5600 136.0000 1.0000
4.5680 146.0000 1.0000
4.5760 171.0000 1.0000
4.5840 189.0000 1.0000
4.5920 204.0000 1.0000
4.6000 180.0000 1.0000
4.6080 127.0000 1.0000
4.6160 114.0000 1.0000
4.6240 91.0000 1.0000
4.6320 87.0000 1.0000
4.6400 87.0000 1.0000
4.6480 105.0000 1.0000
4.6560 105.0000 1.0000
4.6640 145.0000 1.0000
4.6720 126.0000 1.0000
4.6800 156.0000 1.0000
4.6880 151.0000 1.0000
4.6960 135.0000 1.0000
4.7040 125.0000 1.0000
4.7120 89.0000 1.0000
4.7200 96.0000 1.0000
4.7280 87.0000 1.0000
4.7360 99.0000 1.0000
4.7440 82.0000 1.0000
4.7520 112.0000 1.0000
4.7600 130.0000 1.0000
4.7680 124.0000 1.0000
4.7760 119.0000 1.0000
4.7840 98.0000 1.0000
4.7920 88.0000 1.0000
4.8000 92.0000 1.0000
4.8080 91.0000 1.0000
4.8160 77.0000 1.0000
4.8240 69.0000 1.0000
4.8320 93.0000 1.0000
4.8400 107.0000 1.0000
4.8480 108.0000 1.0000
4.8560 102.0000 1.0000
4.8640 116.0000 1.0000
4.8720 94.0000 1.0000
4.8800 73.0000 1.0000
4.8880 83.0000 1.0000
4.8960 53.0000 1.0000
4.9040 61.0000 1.0000
4.9120 70.0000 1.0000
4.9200 70.0000 1.0000
4.9280 80.0000 1.0000
4.9360 85.0000 1.0000
4.9440 95.0000 1.0000
4.9520 82.0000 1.0000
4.9600 102.0000 1.0000
4.9680 90.0000 1.0000
4.9760 66.0000 1.0000
4.9840 61.0000 1.0000
4.9920 69.0000 1.0000
5.0000 60.0000 1.0000
5.0080 55.0000 1.0000
5.0160 50.0000 1.0000
5.0240 85.0000 1.0000
5.0320 67.0000 1.0000
5.0400 89.0000 1.0000
5.0480 92.0000 1.0000
5.0560 66.0000 1.0000
5.0640 62.0000 1.0000
5.0720 53.0000 1.0000
5.0800 43.0000 1.0000
5.0880 39.0000 1.0000
5.0960 56.0000 1.0000
5.1040 51.0000 1.0000
5.1120 65.0000 1.0000
5.1200 81.0000 1.0000
5.1280 78.0000 1.0000
5.1360 67.0000 1.0000
5.1440 63.0000 1.0000
5.1520 61.0000 1.0000
5.1600 69.0000 1.0000
5.1680 49.0000 1.0000
5.1760 33.0000 1.0000
5.1840 45.0000 1.0000
5.1920 35.0000 1.0000
5.2000 42.0000 1.0000
5.2080 63.0000 1.0000
5.2160 59.0000 1.0000
5.2240 66.0000 1.0000
5.2320 74.0000 1.0000
5.2400 51.0000 1.0000
5.2480 35.0000 1.0000
5.2560 45.0000 1.0000
5.2640 31.0000 1.0000
5.2720 26.0000 1.0000
5.2800 43.0000 1.0000
5.2880 42.0000 1.0000
5.2960 39.0000 1.0000
5.3040 50.0000 1.0000
5.3120 53.0000 1.0000
5.3200 54.0000 1.0000
5.3280 44.0000 1.0000
5.3360 41.0000 1.0000
5.3440 25.0000 1.0000
5.3520 29.0000 1.0000
5.3600 33.0000 1.0000
5.3680 29.0000 1.0000
5.3760 24.0000 1.0000
5.3840 37.0000 1.0000
5.3920 34.0000 1.0000
5.4000 36.0000 1.0000
5.4080 29.0000 1.0000
5.4160 41.0000 1.0000
5.4240 38.0000 1.0000
5.4320 31.0000 1.0000
5.4400 27.0000 1.0000
5.4480 26.0000 1.0000
5.4560 21.0000 1.0000
5.4640 38.0000 1.0000
5.4720 27.0000 1.0000
5.4800 33.0000 1.0000
5.4880 35.0000 1.0000
5.4960 39.0000 1.0000
5.5040 36.0000 1.0000
5.5120 28.0000 1.0000
5.5200 30.0000 1.0000
5.5280 22.0000 1.0000
5.5360 24.0000 1.0000
5.5440 21.0000 1.0000
5.5520 25.0000 1.0000
5.5600 26.0000 1.0000
5.5680 29.0000 1.0000
5.5760 42.0000 1.0000
5.5840 33.0000 1.0000
5.5920 25.0000 1.0000
5.6000 26.0000 1.0000
5.6080 25.0000 1.0000
5.6160 28.0000 1.0000
5.6240 21.0000 1.0000
5.6320 18.0000 1.0000
5.6400 27.0000 1.0000
5.6480 22.0000 1.0000
5.6560 20.0000 1.0000
5.6640 30.0000 1.0000
5.6720 33.0000 1.0000
5.6800 34.0000 1.0000
5.6880 33.0000 1.0000
5.6960 24.0000 1.0000
5.7040 27.0000 1.0000
5.7120 14.0000 1.0000
5.7200 20.0000 1.0000
5.7280 22.0000 1.0000
5.7360 21.0000 1.0000
5.7440 16.0000 1.0000
5.7520 21.0000 1.0000
5.7600 23.0000 1.0000
5.7680 28.0000 1.0000
5.7760 26.0000 1.0000
5.7840 20.0000 1.0000
5.7920 23.0000 1.0000
5.8000 17.0000 1.0000
5.8080 25.0000 1.0000
5.8160 19.0000 1.0000
5.8240 15.0000 1.0000
5.8320 20.0000 1.0000
5.8400 22.0000 1.0000
5.8480 17.0000 1.0000
5.8560 18.0000 1.0000
5.8640 23.0000 1.0000
5.8720 21.0000 1.0000
5.8800 17.0000 1.0000
5.8880 22.0000 1.0000
5.8960 11.0000 1.0000
5.9040 25.0000 1.0000
5.9120 14.0000 1.0000
5.9200 14.0000 1.0000
5.9280 15.0000 1.0000
5.9360 13.0000 1.0000
5.9440 23.0000 1.0000
5.9520 23.0000 1.0000
5.9600 23.0000 1.0000
5.9680 14.0000 1.0000
5.9760 18.0000 1.0000
5.9840 18.0000 1.0000
5.9920 18.0000 1.0000
6.0000 16.0000 1.0000
*RAS_INT_END
*RAS_TEMPERATURE_START
*RAS_TEMPERATURE_END
*RAS_DATA_END