File: polarization-foils-XR-master/data/20210331-1_2V022501 Fe20m.ras
*RAS_DATA_START
*RAS_HEADER_START
*DISP_FMT_X "%.3f"
*DISP_FMT_Y "%.0f"
*DISP_FULLSCALE "74114103.8800000100"
*DISP_LINE_COLOR "255.0000000000"
*DISP_LINE_STYLE "0.0000000000"
*DISP_LINE_WIDTH "0.2500000000"
*DISP_NOTE "測定データ-2"
*DISP_OFFSET_Y "0.0000000000"
*DISP_PEAKSEARCH_UNIT_Y "cps"
*DISP_RANGE_BOTTOM "0.0100000000"
*DISP_RANGE_LEFT "0.0000000000"
*DISP_RANGE_LOGCUTOFF "0.0100000000"
*DISP_RANGE_RIGHT "6.0000000000"
*DISP_RANGE_TOP "74114103.8800000100"
*DISP_SCALE_MODE_Y "2.0000000000"
*DISP_TAB_NAME "2θ/ω"
*DISP_TITLE_Y "強度"
*DISP_UNIT_Y "cps"
*DISP_WINDOW_NAME "MSG_MACROENGINE"
*FILE_COMMENT " "
*FILE_MD5 ""
*FILE_MEMO "600 120mA 150V -65deg phi440(4t) ellictic"
*FILE_OPERATOR "User1"
*FILE_PART_ID "MEAS_KHP2_00055"
*FILE_SAMPLE "2V022501 Fe20m Hirayama  left"
*FILE_TYPE "RAS_RAW"
*FILE_USERGROUP "システムマネージャ"
*FILE_VERSION "1.0000000000"
*HW_ATTACHMENT_ID "ATT0022"
*HW_ATTACHMENT_NAME "RxRy|RxRy"
*HW_COUNTER_ID-0 "CUT0021"
*HW_COUNTER_ID-1 "CUT0020"
*HW_COUNTER_ID-2 ""
*HW_COUNTER_ID-3 "CSL0021"
*HW_COUNTER_ID-4 "CMC0021"
*HW_COUNTER_NAME-0 "SC-70|SC-70"
*HW_COUNTER_NAME-1 "None|None"
*HW_COUNTER_NAME-2 ""
*HW_COUNTER_NAME-3 "BBM|BBM"
*HW_COUNTER_NAME-4 "検出器モノクロメータ|Detector monochromator"
*HW_COUNTER_SELECT_NAME "SC-70|SC-70"
*HW_ECP_HV "626.0000000000"
*HW_ECP_HV_UNIT "V"
*HW_GONIOMETER_ID "GON0024"
*HW_GONIOMETER_NAME "SmartLab(In-plane)|SmartLab(In-plane)"
*HW_GONIOMETER_RADIUS-0 "90.0"
*HW_GONIOMETER_RADIUS-1 "114.0"
*HW_GONIOMETER_RADIUS-2 "190.0"
*HW_GONIOMETER_RADIUS-3 "300.0"
*HW_GONIOMETER_RADIUS-4 "187.0"
*HW_GONIOMETER_RADIUS-5 "300.0"
*HW_GONIOMETER_RADIUS-6 "113.0"
*HW_GONIOMETER_RADIUS-7 "331.0"
*HW_I_OPT_ID-0 "CBO0021"
*HW_I_OPT_ID-1 "ICR0021"
*HW_I_OPT_ID-2 "ISL0021"
*HW_I_OPT_ID-3 "ISO0021"
*HW_I_OPT_ID-4 "IAD0021"
*HW_I_OPT_ID-5 "IPR0001"
*HW_I_OPT_NAME-0 "CBOユニット|CBO unit"
*HW_I_OPT_NAME-1 "標準入射光学ユニット|Standard incident optical unit"
*HW_I_OPT_NAME-2 "標準入射スリットボックス|Standard incident slit box"
*HW_I_OPT_NAME-3 "入射平行スリット|Incident parallel slit"
*HW_I_OPT_NAME-4 "長手制限スリット|Length limiting slit"
*HW_I_OPT_NAME-5 "None|None"
*HW_R_ATTENUATER_AUTOMODE "1"
*HW_R_OPT_ID-0 "RSS0021"
*HW_R_OPT_ID-1 "RCR0022"
*HW_R_OPT_ID-2 "RSO0021"
*HW_R_OPT_ID-3 "RRS0021"
*HW_R_OPT_ID-4 "ATN0021"
*HW_R_OPT_ID-5 "RFL0021"
*HW_R_OPT_ID-6 "RAD0021"
*HW_R_OPT_NAME-0 "標準受光スリットボックス1|Standard receiving slit box # 1"
*HW_R_OPT_NAME-1 "標準受光光学ユニット1|Standard receiving unit # 1"
*HW_R_OPT_NAME-2 "標準受光光学ユニット2|Standard receiving optical unit # 2"
*HW_R_OPT_NAME-3 "標準受光スリットボックス2|Standard receiving slit box # 2"
*HW_R_OPT_NAME-4 "標準アッテネータ|Standard Attenuator"
*HW_R_OPT_NAME-5 "Cu Kβ|Cu K-beta"
*HW_R_OPT_NAME-6 "調整用受光スリット|Alignment receiving slit"
*HW_SAMPLE_HOLDER_ID "SMP0021"
*HW_SAMPLE_HOLDER_NAME "χφZクレードル|Chi phi Z cradle"
*HW_XG_CURRENT_MAX "200"
*HW_XG_CURRENT_MIN "10"
*HW_XG_CURRENT_RESOLUTION "1"
*HW_XG_CURRENT_UNIT "mA"
*HW_XG_FOCUS "0.4mm x 8mm"
*HW_XG_FOCUS_TYPE "Normal"
*HW_XG_ID "1700"
*HW_XG_NAME "9kW 開放管(45kV 200mA ID:1700)|9kW Rotating anode(45kV 200mA ID:1700)"
*HW_XG_TARGET_ATOMIC_NUMBER "29.0000000000"
*HW_XG_TARGET_NAME "Cu"
*HW_XG_TYPE "Rota"
*HW_XG_VOLTAGE_MAX "45"
*HW_XG_VOLTAGE_MIN "20"
*HW_XG_VOLTAGE_RESOLUTION "1"
*HW_XG_VOLTAGE_UNIT "kV"
*HW_XG_WATT_MAX "9"
*HW_XG_WATT_UNIT "kW"
*HW_XG_WAVE_LENGTH_ALPHA1 "1.540593"
*HW_XG_WAVE_LENGTH_ALPHA2 "1.544414"
*HW_XG_WAVE_LENGTH_BETA "1.392250"
*MEAS_COND_AXIS_NAME-0 "2θ/θ"
*MEAS_COND_AXIS_NAME-1 "2θ"
*MEAS_COND_AXIS_NAME-2 "ω"
*MEAS_COND_AXIS_NAME-3 "χ"
*MEAS_COND_AXIS_NAME-4 "φ"
*MEAS_COND_AXIS_NAME-5 "Z"
*MEAS_COND_AXIS_NAME-6 "Rx"
*MEAS_COND_AXIS_NAME-7 "Ry"
*MEAS_COND_AXIS_NAME-8 "2θ/ω"
*MEAS_COND_AXIS_NAME-9 "2θχ"
*MEAS_COND_AXIS_NAME-10 "2θχ/φ"
*MEAS_COND_AXIS_NAME-11 "α"
*MEAS_COND_AXIS_NAME-12 "β"
*MEAS_COND_AXIS_NAME-13 "θs"
*MEAS_COND_AXIS_NAME-14 "θd"
*MEAS_COND_AXIS_NAME-15 "Ts"
*MEAS_COND_AXIS_NAME-16 "CBO選択スリット"
*MEAS_COND_AXIS_NAME-17 "M"
*MEAS_COND_AXIS_NAME-18 "入射平行スリット"
*MEAS_COND_AXIS_NAME-19 "入射スリット"
*MEAS_COND_AXIS_NAME-20 ""
*MEAS_COND_AXIS_NAME-21 "Zs"
*MEAS_COND_AXIS_NAME-22 "入射光学素子"
*MEAS_COND_AXIS_NAME-23 "ωm"
*MEAS_COND_AXIS_NAME-24 "長手制限スリット"
*MEAS_COND_AXIS_NAME-25 "センタースリット"
*MEAS_COND_AXIS_NAME-26 "フィルター"
*MEAS_COND_AXIS_NAME-27 "受光スリット1"
*MEAS_COND_AXIS_NAME-28 "受光スリット2"
*MEAS_COND_AXIS_NAME-29 "受光光学素子"
*MEAS_COND_AXIS_NAME-30 "受光平行スリット"
*MEAS_COND_AXIS_NAME-31 "調整用受光スリット"
*MEAS_COND_AXIS_NAME-32 ""
*MEAS_COND_AXIS_NAME-33 ""
*MEAS_COND_AXIS_NAME-34 "Zd"
*MEAS_COND_AXIS_NAME-35 "アッテネータ"
*MEAS_COND_AXIS_NAME-36 "検出器モノクロメータ"
*MEAS_COND_AXIS_NAME-37 "モノクロメータスリット"
*MEAS_COND_AXIS_NAME-38 "2θB"
*MEAS_COND_AXIS_NAME-39 ""
*MEAS_COND_AXIS_NAME-40 ""
*MEAS_COND_AXIS_NAME-41 "プライマリビーム"
*MEAS_COND_AXIS_NAME-42 "HV"
*MEAS_COND_AXIS_NAME-43 "PHA"
*MEAS_COND_AXIS_NAME_INTERNAL-0 "TwoThetaTheta"
*MEAS_COND_AXIS_NAME_INTERNAL-1 "TwoTheta"
*MEAS_COND_AXIS_NAME_INTERNAL-2 "Omega"
*MEAS_COND_AXIS_NAME_INTERNAL-3 "Chi"
*MEAS_COND_AXIS_NAME_INTERNAL-4 "Phi"
*MEAS_COND_AXIS_NAME_INTERNAL-5 "Z"
*MEAS_COND_AXIS_NAME_INTERNAL-6 "Rx"
*MEAS_COND_AXIS_NAME_INTERNAL-7 "Ry"
*MEAS_COND_AXIS_NAME_INTERNAL-8 "TwoThetaOmega"
*MEAS_COND_AXIS_NAME_INTERNAL-9 "TwoThetaChi"
*MEAS_COND_AXIS_NAME_INTERNAL-10 "TwoThetaChiPhi"
*MEAS_COND_AXIS_NAME_INTERNAL-11 "Alpha"
*MEAS_COND_AXIS_NAME_INTERNAL-12 "Beta"
*MEAS_COND_AXIS_NAME_INTERNAL-13 "ThetaS"
*MEAS_COND_AXIS_NAME_INTERNAL-14 "ThetaD"
*MEAS_COND_AXIS_NAME_INTERNAL-15 "Ts"
*MEAS_COND_AXIS_NAME_INTERNAL-16 "CBO"
*MEAS_COND_AXIS_NAME_INTERNAL-17 "CBO-M"
*MEAS_COND_AXIS_NAME_INTERNAL-18 "IncidentSollerSlit"
*MEAS_COND_AXIS_NAME_INTERNAL-19 "IncidentSlitBox"
*MEAS_COND_AXIS_NAME_INTERNAL-20 "IncidentSlitBox-_Axis"
*MEAS_COND_AXIS_NAME_INTERNAL-21 "Zs"
*MEAS_COND_AXIS_NAME_INTERNAL-22 "IncidentMonochromator"
*MEAS_COND_AXIS_NAME_INTERNAL-23 "IncidentMonochromator-OmegaM"
*MEAS_COND_AXIS_NAME_INTERNAL-24 "IncidentAxdSlit"
*MEAS_COND_AXIS_NAME_INTERNAL-25 "CenterSlit"
*MEAS_COND_AXIS_NAME_INTERNAL-26 "Filter"
*MEAS_COND_AXIS_NAME_INTERNAL-27 "ReceivingSlitBox1"
*MEAS_COND_AXIS_NAME_INTERNAL-28 "ReceivingSlitBox2"
*MEAS_COND_AXIS_NAME_INTERNAL-29 "ReceivingOptics"
*MEAS_COND_AXIS_NAME_INTERNAL-30 "ReceivingSollerSlit"
*MEAS_COND_AXIS_NAME_INTERNAL-31 "ReceivingAxdSlit"
*MEAS_COND_AXIS_NAME_INTERNAL-32 "ReceivingSlitBox1-_Axis"
*MEAS_COND_AXIS_NAME_INTERNAL-33 "ReceivingSlitBox2-_Axis"
*MEAS_COND_AXIS_NAME_INTERNAL-34 "ReceivingSlitBox2-Zd"
*MEAS_COND_AXIS_NAME_INTERNAL-35 "Attenuator"
*MEAS_COND_AXIS_NAME_INTERNAL-36 "CounterMonochromator"
*MEAS_COND_AXIS_NAME_INTERNAL-37 "CounterSlit"
*MEAS_COND_AXIS_NAME_INTERNAL-38 "TwoThetaB"
*MEAS_COND_AXIS_NAME_INTERNAL-39 "AlphaR"
*MEAS_COND_AXIS_NAME_INTERNAL-40 "BetaR"
*MEAS_COND_AXIS_NAME_INTERNAL-41 "IncidentPrimary"
*MEAS_COND_AXIS_NAME_INTERNAL-42 "HV"
*MEAS_COND_AXIS_NAME_INTERNAL-43 "PHA"
*MEAS_COND_AXIS_NAME_MAGICNO-0 "83951616.0000000000"
*MEAS_COND_AXIS_NAME_MAGICNO-1 "268632064.0000000000"
*MEAS_COND_AXIS_NAME_MAGICNO-2 "268500992.0000000000"
*MEAS_COND_AXIS_NAME_MAGICNO-3 "268500992.0000000000"
*MEAS_COND_AXIS_NAME_MAGICNO-4 "268500992.0000000000"
*MEAS_COND_AXIS_NAME_MAGICNO-5 "285278208.0000000000"
*MEAS_COND_AXIS_NAME_MAGICNO-6 "285278208.0000000000"
*MEAS_COND_AXIS_NAME_MAGICNO-7 "285278208.0000000000"
*MEAS_COND_AXIS_NAME_MAGICNO-8 "83951616.0000000000"
*MEAS_COND_AXIS_NAME_MAGICNO-9 "268632064.0000000000"
*MEAS_COND_AXIS_NAME_MAGICNO-10 "83951616.0000000000"
*MEAS_COND_AXIS_NAME_MAGICNO-11 "17039360.0000000000"
*MEAS_COND_AXIS_NAME_MAGICNO-12 "17039360.0000000000"
*MEAS_COND_AXIS_NAME_MAGICNO-13 "131072.0000000000"
*MEAS_COND_AXIS_NAME_MAGICNO-14 "131072.0000000000"
*MEAS_COND_AXIS_NAME_MAGICNO-15 "318898176.0000000000"
*MEAS_COND_AXIS_NAME_MAGICNO-16 "20971521.0000000000"
*MEAS_COND_AXIS_NAME_MAGICNO-17 "285343744.0000000000"
*MEAS_COND_AXIS_NAME_MAGICNO-18 "20971521.0000000000"
*MEAS_COND_AXIS_NAME_MAGICNO-19 "22020097.0000000000"
*MEAS_COND_AXIS_NAME_MAGICNO-20 "25165824.0000000000"
*MEAS_COND_AXIS_NAME_MAGICNO-21 "318898176.0000000000"
*MEAS_COND_AXIS_NAME_MAGICNO-22 "20971521.0000000000"
*MEAS_COND_AXIS_NAME_MAGICNO-23 "285343744.0000000000"
*MEAS_COND_AXIS_NAME_MAGICNO-24 "20971521.0000000000"
*MEAS_COND_AXIS_NAME_MAGICNO-25 "20971521.0000000000"
*MEAS_COND_AXIS_NAME_MAGICNO-26 "20971521.0000000000"
*MEAS_COND_AXIS_NAME_MAGICNO-27 "23068673.0000000000"
*MEAS_COND_AXIS_NAME_MAGICNO-28 "23068673.0000000000"
*MEAS_COND_AXIS_NAME_MAGICNO-29 "20971521.0000000000"
*MEAS_COND_AXIS_NAME_MAGICNO-30 "20971521.0000000000"
*MEAS_COND_AXIS_NAME_MAGICNO-31 "20971521.0000000000"
*MEAS_COND_AXIS_NAME_MAGICNO-32 "25165824.0000000000"
*MEAS_COND_AXIS_NAME_MAGICNO-33 "25165824.0000000000"
*MEAS_COND_AXIS_NAME_MAGICNO-34 "285343744.0000000000"
*MEAS_COND_AXIS_NAME_MAGICNO-35 "17301505.0000000000"
*MEAS_COND_AXIS_NAME_MAGICNO-36 "20971521.0000000000"
*MEAS_COND_AXIS_NAME_MAGICNO-37 "20971521.0000000000"
*MEAS_COND_AXIS_NAME_MAGICNO-38 "17039360.0000000000"
*MEAS_COND_AXIS_NAME_MAGICNO-39 "8388608.0000000000"
*MEAS_COND_AXIS_NAME_MAGICNO-40 "8388608.0000000000"
*MEAS_COND_AXIS_NAME_MAGICNO-41 "20971521.0000000000"
*MEAS_COND_AXIS_NAME_MAGICNO-42 "0.0000000000"
*MEAS_COND_AXIS_NAME_MAGICNO-43 "0.0000000000"
*MEAS_COND_AXIS_OFFSET-0 "-"
*MEAS_COND_AXIS_OFFSET-1 "1.2881000000"
*MEAS_COND_AXIS_OFFSET-2 "1.3922000000"
*MEAS_COND_AXIS_OFFSET-3 "0.0000000000"
*MEAS_COND_AXIS_OFFSET-4 "0.0000000000"
*MEAS_COND_AXIS_OFFSET-5 "-"
*MEAS_COND_AXIS_OFFSET-6 "-"
*MEAS_COND_AXIS_OFFSET-7 "-"
*MEAS_COND_AXIS_OFFSET-8 "-"
*MEAS_COND_AXIS_OFFSET-9 "0.0000000000"
*MEAS_COND_AXIS_OFFSET-10 "-"
*MEAS_COND_AXIS_OFFSET-11 "-"
*MEAS_COND_AXIS_OFFSET-12 "-"
*MEAS_COND_AXIS_OFFSET-13 "1.3922000000"
*MEAS_COND_AXIS_OFFSET-14 "-0.1041000000"
*MEAS_COND_AXIS_OFFSET-15 "-"
*MEAS_COND_AXIS_OFFSET-16 "-"
*MEAS_COND_AXIS_OFFSET-17 "-"
*MEAS_COND_AXIS_OFFSET-18 "-"
*MEAS_COND_AXIS_OFFSET-19 "-"
*MEAS_COND_AXIS_OFFSET-20 "-"
*MEAS_COND_AXIS_OFFSET-21 "-"
*MEAS_COND_AXIS_OFFSET-22 "-"
*MEAS_COND_AXIS_OFFSET-23 "-"
*MEAS_COND_AXIS_OFFSET-24 "-"
*MEAS_COND_AXIS_OFFSET-25 "-"
*MEAS_COND_AXIS_OFFSET-26 "-"
*MEAS_COND_AXIS_OFFSET-27 "-"
*MEAS_COND_AXIS_OFFSET-28 "-"
*MEAS_COND_AXIS_OFFSET-29 "-"
*MEAS_COND_AXIS_OFFSET-30 "-"
*MEAS_COND_AXIS_OFFSET-31 "-"
*MEAS_COND_AXIS_OFFSET-32 "-"
*MEAS_COND_AXIS_OFFSET-33 "-"
*MEAS_COND_AXIS_OFFSET-34 "-"
*MEAS_COND_AXIS_OFFSET-35 "-"
*MEAS_COND_AXIS_OFFSET-36 "-"
*MEAS_COND_AXIS_OFFSET-37 "-"
*MEAS_COND_AXIS_OFFSET-38 "-"
*MEAS_COND_AXIS_OFFSET-39 "0.0000000000"
*MEAS_COND_AXIS_OFFSET-40 "0.0000000000"
*MEAS_COND_AXIS_OFFSET-41 "-"
*MEAS_COND_AXIS_OFFSET-42 "-"
*MEAS_COND_AXIS_OFFSET-43 "-"
*MEAS_COND_AXIS_POSITION-0 "-0.0020000000"
*MEAS_COND_AXIS_POSITION-1 "-0.0020000000"
*MEAS_COND_AXIS_POSITION-2 "-0.0010000000"
*MEAS_COND_AXIS_POSITION-3 "-0.1540000000"
*MEAS_COND_AXIS_POSITION-4 "0.0000000000"
*MEAS_COND_AXIS_POSITION-5 "-0.3896000000"
*MEAS_COND_AXIS_POSITION-6 "0.0000000000"
*MEAS_COND_AXIS_POSITION-7 "0.0000000000"
*MEAS_COND_AXIS_POSITION-8 "-0.0020000000"
*MEAS_COND_AXIS_POSITION-9 "0.0000000000"
*MEAS_COND_AXIS_POSITION-10 "0.0000000000"
*MEAS_COND_AXIS_POSITION-11 "-89.9800000000"
*MEAS_COND_AXIS_POSITION-12 "0.0000000000"
*MEAS_COND_AXIS_POSITION-13 "-0.0010000000"
*MEAS_COND_AXIS_POSITION-14 "-0.0010000000"
*MEAS_COND_AXIS_POSITION-15 "-6.2162500000"
*MEAS_COND_AXIS_POSITION-16 "PB"
*MEAS_COND_AXIS_POSITION-17 "0.0000000000"
*MEAS_COND_AXIS_POSITION-18 "Soller_slit_open_s"
*MEAS_COND_AXIS_POSITION-19 "0.100mm"
*MEAS_COND_AXIS_POSITION-20 "0.1000000000"
*MEAS_COND_AXIS_POSITION-21 "-1.7100000000"
*MEAS_COND_AXIS_POSITION-22 "Ge(220)x2"
*MEAS_COND_AXIS_POSITION-23 "0.0000000000"
*MEAS_COND_AXIS_POSITION-24 "10.0mm"
*MEAS_COND_AXIS_POSITION-25 "None"
*MEAS_COND_AXIS_POSITION-26 "None"
*MEAS_COND_AXIS_POSITION-27 "0.200mm"
*MEAS_COND_AXIS_POSITION-28 "0.200mm"
*MEAS_COND_AXIS_POSITION-29 "PSA_open"
*MEAS_COND_AXIS_POSITION-30 "Soller_slit_5.0deg"
*MEAS_COND_AXIS_POSITION-31 "None"
*MEAS_COND_AXIS_POSITION-32 "0.2000000000"
*MEAS_COND_AXIS_POSITION-33 "0.2000000000"
*MEAS_COND_AXIS_POSITION-34 "0.2290600000"
*MEAS_COND_AXIS_POSITION-35 "1/10000"
*MEAS_COND_AXIS_POSITION-36 "None"
*MEAS_COND_AXIS_POSITION-37 "None"
*MEAS_COND_AXIS_POSITION-38 "0.0020000000"
*MEAS_COND_AXIS_POSITION-39 "0.0000000000"
*MEAS_COND_AXIS_POSITION-40 "0.0000000000"
*MEAS_COND_AXIS_POSITION-41 "None"
*MEAS_COND_AXIS_POSITION-42 "626.0000000000"
*MEAS_COND_AXIS_POSITION-43 "603.7500000000"
*MEAS_COND_AXIS_UNIT-0 "deg"
*MEAS_COND_AXIS_UNIT-1 "deg"
*MEAS_COND_AXIS_UNIT-2 "deg"
*MEAS_COND_AXIS_UNIT-3 "deg"
*MEAS_COND_AXIS_UNIT-4 "deg"
*MEAS_COND_AXIS_UNIT-5 "mm"
*MEAS_COND_AXIS_UNIT-6 "deg"
*MEAS_COND_AXIS_UNIT-7 "deg"
*MEAS_COND_AXIS_UNIT-8 "deg"
*MEAS_COND_AXIS_UNIT-9 "deg"
*MEAS_COND_AXIS_UNIT-10 "deg"
*MEAS_COND_AXIS_UNIT-11 "deg"
*MEAS_COND_AXIS_UNIT-12 "deg"
*MEAS_COND_AXIS_UNIT-13 "deg"
*MEAS_COND_AXIS_UNIT-14 "deg"
*MEAS_COND_AXIS_UNIT-15 "mm"
*MEAS_COND_AXIS_UNIT-16 ""
*MEAS_COND_AXIS_UNIT-17 "pulse"
*MEAS_COND_AXIS_UNIT-18 ""
*MEAS_COND_AXIS_UNIT-19 ""
*MEAS_COND_AXIS_UNIT-20 "mm"
*MEAS_COND_AXIS_UNIT-21 "mm"
*MEAS_COND_AXIS_UNIT-22 ""
*MEAS_COND_AXIS_UNIT-23 "pulse"
*MEAS_COND_AXIS_UNIT-24 ""
*MEAS_COND_AXIS_UNIT-25 ""
*MEAS_COND_AXIS_UNIT-26 ""
*MEAS_COND_AXIS_UNIT-27 ""
*MEAS_COND_AXIS_UNIT-28 ""
*MEAS_COND_AXIS_UNIT-29 ""
*MEAS_COND_AXIS_UNIT-30 ""
*MEAS_COND_AXIS_UNIT-31 ""
*MEAS_COND_AXIS_UNIT-32 "mm"
*MEAS_COND_AXIS_UNIT-33 "mm"
*MEAS_COND_AXIS_UNIT-34 "mm"
*MEAS_COND_AXIS_UNIT-35 ""
*MEAS_COND_AXIS_UNIT-36 ""
*MEAS_COND_AXIS_UNIT-37 ""
*MEAS_COND_AXIS_UNIT-38 "deg"
*MEAS_COND_AXIS_UNIT-39 "deg"
*MEAS_COND_AXIS_UNIT-40 "deg"
*MEAS_COND_AXIS_UNIT-41 ""
*MEAS_COND_AXIS_UNIT-42 "V"
*MEAS_COND_AXIS_UNIT-43 "mV"
*MEAS_COND_COUNTER_CNTLOSS_CORR "1.0000000000"
*MEAS_COND_COUNTER_PHABASE "603.7500000000"
*MEAS_COND_COUNTER_PHAWINDOW "855.0000000000"
*MEAS_COND_COUNTER_PHA_UNIT "mV"
*MEAS_COND_COUNTER_TAUDIFF "0.1777010000"
*MEAS_COND_COUNTER_TAUINT "0.6912320000"
*MEAS_COND_IRRADIATION_MODE "OFF"
*MEAS_COND_IRRADIATION_WIDTH ""
*MEAS_COND_OPT_ATTR "高分解能平行ビームGe(220)x2/受光スリット"
*MEAS_COND_OPT_NAME "@高分解能PB-Ge(220)x2"
*MEAS_COND_UNSYMMETRIC_MODE "OFF"
*MEAS_COND_XG_CURRENT "200.0000000000"
*MEAS_COND_XG_VOLTAGE "45.0000000000"
*MEAS_COND_XG_WAVE_TYPE "Ka1"
*MEAS_DATA_COUNT "1501.0000000000"
*MEAS_SCAN_AXIS_X "2θ/ω"
*MEAS_SCAN_AXIS_X_INTERNAL "TwoThetaOmega"
*MEAS_SCAN_END_TIME "03/31/21 14:15:12"
*MEAS_SCAN_MODE "CONTINUOUS"
*MEAS_SCAN_MONITOR "0"
*MEAS_SCAN_RESOLUTION_X "0.0002"
*MEAS_SCAN_SPEED "0.400000"
*MEAS_SCAN_SPEED_UNIT "deg/min"
*MEAS_SCAN_SPEED_USER "0.4000"
*MEAS_SCAN_START "0.0000000000"
*MEAS_SCAN_START_TIME "03/31/21 13:59:35"
*MEAS_SCAN_STEP "0.0040000000"
*MEAS_SCAN_STOP "6.0000000000"
*MEAS_SCAN_UNIT_X "deg"
*MEAS_SCAN_UNIT_Y "counts"
*RAS_HEADER_END
*RAS_INT_START
0.0000 44243.0000 837.5800
0.0080 41645.0000 837.5800
0.0160 32289.0000 837.5800
0.0240 16582.0000 837.5800
0.0320 5200.0000 837.5800
0.0400 22584.0000 53.5042
0.0480 8858.0000 53.5042
0.0560 5646.0000 53.5042
0.0640 4925.0000 53.5042
0.0720 5236.0000 53.5042
0.0800 5538.0000 53.5042
0.0880 6175.0000 53.5042
0.0960 6849.0005 53.5042
0.1040 8044.0000 53.5042
0.1120 9301.0000 53.5042
0.1200 11419.9990 53.5042
0.1280 14370.0000 53.5042
0.1360 17584.0000 53.5042
0.1440 22017.0000 53.5042
0.1520 27664.0020 53.5042
0.1600 33643.0000 53.5042
0.1680 41155.9961 53.5042
0.1760 49414.0000 53.5042
0.1840 58585.0000 53.5042
0.1920 67188.0000 53.5042
0.2000 77626.0000 53.5042
0.2080 88638.0078 53.5042
0.2160 99359.0000 53.5042
0.2240 110225.0000 53.5042
0.2320 121059.0000 53.5042
0.2400 134223.0000 53.5042
0.2480 145132.0000 53.5042
0.2560 156872.0000 53.5042
0.2640 168874.0000 53.5042
0.2720 180476.0000 53.5042
0.2800 192485.9844 53.5042
0.2880 204906.0000 53.5042
0.2960 217190.0000 53.5042
0.3040 228949.0000 53.5042
0.3120 15229.0000 837.5800
0.3200 15973.0000 837.5800
0.3280 16670.0000 837.5800
0.3360 17406.0000 837.5800
0.3440 18021.0000 837.5800
0.3520 18417.0000 837.5800
0.3600 18850.0000 837.5800
0.3680 19675.0000 837.5800
0.3760 20161.0000 837.5800
0.3840 20632.0000 837.5800
0.3920 20727.0000 837.5800
0.4000 21272.0000 837.5800
0.4080 21678.9980 837.5800
0.4160 21866.0000 837.5800
0.4240 21939.0000 837.5800
0.4320 22373.9980 837.5800
0.4400 22516.9980 837.5800
0.4480 23106.0000 837.5800
0.4560 23327.0000 837.5800
0.4640 23463.0000 837.5800
0.4720 23547.0000 837.5800
0.4800 23892.0000 837.5800
0.4880 23859.0000 837.5800
0.4960 24073.9980 837.5800
0.5040 24062.0000 837.5800
0.5120 24252.0000 837.5800
0.5200 24206.0000 837.5800
0.5280 24097.0000 837.5800
0.5360 24258.0000 837.5800
0.5440 24511.0000 837.5800
0.5520 24367.0000 837.5800
0.5600 24329.0000 837.5800
0.5680 24592.9980 837.5800
0.5760 24301.0000 837.5800
0.5840 24492.0000 837.5800
0.5920 24258.0000 837.5800
0.6000 23929.0000 837.5800
0.6080 23752.0000 837.5800
0.6160 23256.0000 837.5800
0.6240 23294.0000 837.5800
0.6320 22787.0000 837.5800
0.6400 22629.0000 837.5800
0.6480 22073.9980 837.5800
0.6560 22087.0000 837.5800
0.6640 21476.0000 837.5800
0.6720 20340.0000 837.5800
0.6800 20135.0000 837.5800
0.6880 19245.0000 837.5800
0.6960 18675.0000 837.5800
0.7040 17692.0000 837.5800
0.7120 16455.0000 837.5800
0.7200 15423.0000 837.5800
0.7280 14381.0000 837.5800
0.7360 13136.0000 837.5800
0.7440 11963.0010 837.5800
0.7520 10763.0010 837.5800
0.7600 9698.0000 837.5800
0.7680 8740.0000 837.5800
0.7760 7729.0000 837.5800
0.7840 7121.0000 837.5800
0.7920 6504.0000 837.5800
0.8000 6007.0000 837.5800
0.8080 5983.9995 837.5800
0.8160 5483.9995 837.5800
0.8240 5288.0000 837.5800
0.8320 4935.0000 837.5800
0.8400 4641.0000 837.5800
0.8480 4231.0000 837.5800
0.8560 3690.0000 837.5800
0.8640 3211.0002 837.5800
0.8720 44556.0039 53.5042
0.8800 37340.0000 53.5042
0.8880 31789.0000 53.5042
0.8960 27508.0000 53.5042
0.9040 23805.0000 53.5042
0.9120 21219.0000 53.5042
0.9200 19723.0000 53.5042
0.9280 19356.0000 53.5042
0.9360 19285.0000 53.5042
0.9440 20147.0000 53.5042
0.9520 21160.0000 53.5042
0.9600 22214.9980 53.5042
0.9680 23114.0000 53.5042
0.9760 23609.0000 53.5042
0.9840 23776.0000 53.5042
0.9920 23720.0000 53.5042
1.0000 22969.0000 53.5042
1.0080 21832.0020 53.5042
1.0160 20149.0000 53.5042
1.0240 18539.0000 53.5042
1.0320 16530.0000 53.5042
1.0400 14519.0000 53.5042
1.0480 12227.0000 53.5042
1.0560 10434.0000 53.5042
1.0640 8672.0000 53.5042
1.0720 6874.0000 53.5042
1.0800 5373.0000 53.5042
1.0880 4450.0000 53.5042
1.0960 3684.0000 53.5042
1.1040 3313.0002 53.5042
1.1120 3267.0000 53.5042
1.1200 3503.0000 53.5042
1.1280 3802.0000 53.5042
1.1360 4303.0000 53.5042
1.1440 5005.0000 53.5042
1.1520 5590.9995 53.5042
1.1600 6227.0000 53.5042
1.1680 6884.0000 53.5042
1.1760 7145.0000 53.5042
1.1840 7552.0000 53.5042
1.1920 7724.0000 53.5042
1.2000 7707.0000 53.5042
1.2080 7559.0000 53.5042
1.2160 7181.0000 53.5042
1.2240 6735.0000 53.5042
1.2320 6123.0000 53.5042
1.2400 5637.0000 53.5042
1.2480 4761.0000 53.5042
1.2560 4059.0000 53.5042
1.2640 3423.0000 53.5042
1.2720 2652.0000 53.5042
1.2800 2207.0000 53.5042
1.2880 1572.0000 53.5042
1.2960 63465.0000 1.0000
1.3040 44364.0000 1.0000
1.3120 31632.0000 1.0000
1.3200 23874.0000 1.0000
1.3280 22217.0000 1.0000
1.3360 25181.0000 1.0000
1.3440 32757.0000 1.0000
1.3520 43150.0000 1.0000
1.3600 56679.0000 1.0000
1.3680 70764.0000 1.0000
1.3760 85572.0000 1.0000
1.3840 101158.0000 1.0000
1.3920 113978.0000 1.0000
1.4000 125312.0000 1.0000
1.4080 133679.0000 1.0000
1.4160 141259.0000 1.0000
1.4240 143819.0000 1.0000
1.4320 142508.0000 1.0000
1.4400 140359.0000 1.0000
1.4480 134787.0000 1.0000
1.4560 125918.0000 1.0000
1.4640 115809.0000 1.0000
1.4720 103553.0000 1.0000
1.4800 91516.0000 1.0000
1.4880 77941.0000 1.0000
1.4960 63799.0000 1.0000
1.5040 51182.0000 1.0000
1.5120 39230.0000 1.0000
1.5200 28809.0000 1.0000
1.5280 19665.0000 1.0000
1.5360 12350.0000 1.0000
1.5440 7120.0000 1.0000
1.5520 3597.0000 1.0000
1.5600 2184.0000 1.0000
1.5680 2379.0000 1.0000
1.5760 4055.0000 1.0000
1.5840 7250.0000 1.0000
1.5920 11339.0000 1.0000
1.6000 16312.0000 1.0000
1.6080 21594.0000 1.0000
1.6160 27158.0000 1.0000
1.6240 32495.0000 1.0000
1.6320 37421.0000 1.0000
1.6400 41003.0000 1.0000
1.6480 44448.0000 1.0000
1.6560 47370.0000 1.0000
1.6640 48631.0000 1.0000
1.6720 48859.0000 1.0000
1.6800 48425.0000 1.0000
1.6880 46781.0000 1.0000
1.6960 44251.0000 1.0000
1.7040 40878.0000 1.0000
1.7120 37436.0000 1.0000
1.7200 33271.0000 1.0000
1.7280 28450.0000 1.0000
1.7360 24565.0000 1.0000
1.7440 19891.0000 1.0000
1.7520 15840.0000 1.0000
1.7600 12230.0000 1.0000
1.7680 8815.0000 1.0000
1.7760 6557.0000 1.0000
1.7840 4419.0000 1.0000
1.7920 3051.0000 1.0000
1.8000 2347.0000 1.0000
1.8080 2242.0000 1.0000
1.8160 2596.0000 1.0000
1.8240 3638.0000 1.0000
1.8320 4831.0000 1.0000
1.8400 6477.0000 1.0000
1.8480 7972.0000 1.0000
1.8560 9925.0000 1.0000
1.8640 11545.0000 1.0000
1.8720 13520.0000 1.0000
1.8800 14826.0000 1.0000
1.8880 16236.0000 1.0000
1.8960 16964.0000 1.0000
1.9040 17707.0000 1.0000
1.9120 17831.0000 1.0000
1.9200 17604.0000 1.0000
1.9280 17141.0000 1.0000
1.9360 16142.0000 1.0000
1.9440 15082.0000 1.0000
1.9520 13961.0000 1.0000
1.9600 12411.0000 1.0000
1.9680 11007.0000 1.0000
1.9760 9431.0000 1.0000
1.9840 7894.0000 1.0000
1.9920 6656.0000 1.0000
2.0000 5451.0000 1.0000
2.0080 4266.0000 1.0000
2.0160 3415.0000 1.0000
2.0240 2955.0000 1.0000
2.0320 2532.0000 1.0000
2.0400 2391.0000 1.0000
2.0480 2577.0000 1.0000
2.0560 2842.0000 1.0000
2.0640 3286.0000 1.0000
2.0720 3902.0000 1.0000
2.0800 4544.0000 1.0000
2.0880 5187.0000 1.0000
2.0960 6067.0000 1.0000
2.1040 6597.0000 1.0000
2.1120 7334.0000 1.0000
2.1200 7752.0000 1.0000
2.1280 8441.0000 1.0000
2.1360 8742.0000 1.0000
2.1440 9035.0000 1.0000
2.1520 8754.0000 1.0000
2.1600 8518.0000 1.0000
2.1680 8171.0000 1.0000
2.1760 7686.0000 1.0000
2.1840 6851.0000 1.0000
2.1920 6492.0000 1.0000
2.2000 5600.0000 1.0000
2.2080 4714.0000 1.0000
2.2160 3939.0000 1.0000
2.2240 3200.0000 1.0000
2.2320 2604.0000 1.0000
2.2400 2014.0000 1.0000
2.2480 1601.0000 1.0000
2.2560 1213.0000 1.0000
2.2640 1119.0000 1.0000
2.2720 1056.0000 1.0000
2.2800 1182.0000 1.0000
2.2880 1415.0000 1.0000
2.2960 1740.0000 1.0000
2.3040 2061.0000 1.0000
2.3120 2620.0000 1.0000
2.3200 3165.0000 1.0000
2.3280 3900.0000 1.0000
2.3360 4330.0000 1.0000
2.3440 4890.0000 1.0000
2.3520 5402.0000 1.0000
2.3600 5837.0000 1.0000
2.3680 6114.0000 1.0000
2.3760 6343.0000 1.0000
2.3840 6566.0000 1.0000
2.3920 6509.0000 1.0000
2.4000 6402.0000 1.0000
2.4080 6268.0000 1.0000
2.4160 5844.0000 1.0000
2.4240 5353.0000 1.0000
2.4320 4736.0000 1.0000
2.4400 4349.0000 1.0000
2.4480 3648.0000 1.0000
2.4560 3050.0000 1.0000
2.4640 2467.0000 1.0000
2.4720 1917.0000 1.0000
2.4800 1428.0000 1.0000
2.4880 987.0000 1.0000
2.4960 672.0000 1.0000
2.5040 401.0000 1.0000
2.5120 261.0000 1.0000
2.5200 270.0000 1.0000
2.5280 357.0000 1.0000
2.5360 551.0000 1.0000
2.5440 812.0000 1.0000
2.5520 1167.0000 1.0000
2.5600 1487.0000 1.0000
2.5680 2022.0000 1.0000
2.5760 2539.0000 1.0000
2.5840 2926.0000 1.0000
2.5920 3434.0000 1.0000
2.6000 4038.0000 1.0000
2.6080 4455.0000 1.0000
2.6160 4637.0000 1.0000
2.6240 4906.0000 1.0000
2.6320 5283.0000 1.0000
2.6400 5207.0000 1.0000
2.6480 5276.0000 1.0000
2.6560 5211.0000 1.0000
2.6640 5123.0000 1.0000
2.6720 4815.0000 1.0000
2.6800 4395.0000 1.0000
2.6880 4060.0000 1.0000
2.6960 3676.0000 1.0000
2.7040 3151.0000 1.0000
2.7120 2648.0000 1.0000
2.7200 2168.0000 1.0000
2.7280 1740.0000 1.0000
2.7360 1282.0000 1.0000
2.7440 932.0000 1.0000
2.7520 592.0000 1.0000
2.7600 377.0000 1.0000
2.7680 210.0000 1.0000
2.7760 134.0000 1.0000
2.7840 108.0000 1.0000
2.7920 195.0000 1.0000
2.8000 381.0000 1.0000
2.8080 591.0000 1.0000
2.8160 872.0000 1.0000
2.8240 1286.0000 1.0000
2.8320 1550.0000 1.0000
2.8400 2038.0000 1.0000
2.8480 2318.0000 1.0000
2.8560 2761.0000 1.0000
2.8640 3168.0000 1.0000
2.8720 3493.0000 1.0000
2.8800 3778.0000 1.0000
2.8880 3979.0000 1.0000
2.8960 4240.0000 1.0000
2.9040 4233.0000 1.0000
2.9120 4242.0000 1.0000
2.9200 4259.0000 1.0000
2.9280 4063.0000 1.0000
2.9360 3932.0000 1.0000
2.9440 3675.0000 1.0000
2.9520 3296.0000 1.0000
2.9600 3129.0000 1.0000
2.9680 2734.0000 1.0000
2.9760 2350.0000 1.0000
2.9840 2082.0000 1.0000
2.9920 1631.0000 1.0000
3.0000 1257.0000 1.0000
3.0080 940.0000 1.0000
3.0160 691.0000 1.0000
3.0240 441.0000 1.0000
3.0320 267.0000 1.0000
3.0400 168.0000 1.0000
3.0480 140.0000 1.0000
3.0560 131.0000 1.0000
3.0640 215.0000 1.0000
3.0720 304.0000 1.0000
3.0800 529.0000 1.0000
3.0880 771.0000 1.0000
3.0960 1017.0000 1.0000
3.1040 1327.0000 1.0000
3.1120 1662.0000 1.0000
3.1200 1912.0000 1.0000
3.1280 2172.0000 1.0000
3.1360 2407.0000 1.0000
3.1440 2747.0000 1.0000
3.1520 2960.0000 1.0000
3.1600 3237.0000 1.0000
3.1680 3274.0000 1.0000
3.1760 3364.0000 1.0000
3.1840 3377.0000 1.0000
3.1920 3306.0000 1.0000
3.2000 3302.0000 1.0000
3.2080 3061.0000 1.0000
3.2160 2879.0000 1.0000
3.2240 2697.0000 1.0000
3.2320 2454.0000 1.0000
3.2400 2122.0000 1.0000
3.2480 1937.0000 1.0000
3.2560 1595.0000 1.0000
3.2640 1276.0000 1.0000
3.2720 1034.0000 1.0000
3.2800 835.0000 1.0000
3.2880 575.0000 1.0000
3.2960 422.0000 1.0000
3.3040 280.0000 1.0000
3.3120 175.0000 1.0000
3.3200 108.0000 1.0000
3.3280 104.0000 1.0000
3.3360 151.0000 1.0000
3.3440 236.0000 1.0000
3.3520 360.0000 1.0000
3.3600 553.0000 1.0000
3.3680 760.0000 1.0000
3.3760 929.0000 1.0000
3.3840 1153.0000 1.0000
3.3920 1361.0000 1.0000
3.4000 1590.0000 1.0000
3.4080 1863.0000 1.0000
3.4160 1939.0000 1.0000
3.4240 2291.0000 1.0000
3.4320 2314.0000 1.0000
3.4400 2498.0000 1.0000
3.4480 2425.0000 1.0000
3.4560 2514.0000 1.0000
3.4640 2548.0000 1.0000
3.4720 2474.0000 1.0000
3.4800 2462.0000 1.0000
3.4880 2288.0000 1.0000
3.4960 2166.0000 1.0000
3.5040 1995.0000 1.0000
3.5120 1740.0000 1.0000
3.5200 1507.0000 1.0000
3.5280 1375.0000 1.0000
3.5360 1123.0000 1.0000
3.5440 943.0000 1.0000
3.5520 754.0000 1.0000
3.5600 569.0000 1.0000
3.5680 410.0000 1.0000
3.5760 282.0000 1.0000
3.5840 187.0000 1.0000
3.5920 133.0000 1.0000
3.6000 111.0000 1.0000
3.6080 117.0000 1.0000
3.6160 177.0000 1.0000
3.6240 216.0000 1.0000
3.6320 301.0000 1.0000
3.6400 419.0000 1.0000
3.6480 606.0000 1.0000
3.6560 739.0000 1.0000
3.6640 905.0000 1.0000
3.6720 1084.0000 1.0000
3.6800 1265.0000 1.0000
3.6880 1332.0000 1.0000
3.6960 1530.0000 1.0000
3.7040 1628.0000 1.0000
3.7120 1615.0000 1.0000
3.7200 1829.0000 1.0000
3.7280 1801.0000 1.0000
3.7360 1908.0000 1.0000
3.7440 1907.0000 1.0000
3.7520 1754.0000 1.0000
3.7600 1768.0000 1.0000
3.7680 1665.0000 1.0000
3.7760 1529.0000 1.0000
3.7840 1346.0000 1.0000
3.7920 1324.0000 1.0000
3.8000 1191.0000 1.0000
3.8080 979.0000 1.0000
3.8160 802.0000 1.0000
3.8240 705.0000 1.0000
3.8320 557.0000 1.0000
3.8400 409.0000 1.0000
3.8480 335.0000 1.0000
3.8560 239.0000 1.0000
3.8640 159.0000 1.0000
3.8720 116.0000 1.0000
3.8800 103.0000 1.0000
3.8880 100.0000 1.0000
3.8960 140.0000 1.0000
3.9040 184.0000 1.0000
3.9120 255.0000 1.0000
3.9200 352.0000 1.0000
3.9280 455.0000 1.0000
3.9360 539.0000 1.0000
3.9440 615.0000 1.0000
3.9520 737.0000 1.0000
3.9600 858.0000 1.0000
3.9680 899.0000 1.0000
3.9760 1046.0000 1.0000
3.9840 1175.0000 1.0000
3.9920 1231.0000 1.0000
4.0000 1273.0000 1.0000
4.0080 1256.0000 1.0000
4.0160 1284.0000 1.0000
4.0240 1327.0000 1.0000
4.0320 1185.0000 1.0000
4.0400 1227.0000 1.0000
4.0480 1146.0000 1.0000
4.0560 1141.0000 1.0000
4.0640 1090.0000 1.0000
4.0720 949.0000 1.0000
4.0800 795.0000 1.0000
4.0880 717.0000 1.0000
4.0960 558.0000 1.0000
4.1040 499.0000 1.0000
4.1120 434.0000 1.0000
4.1200 324.0000 1.0000
4.1280 258.0000 1.0000
4.1360 190.0000 1.0000
4.1440 144.0000 1.0000
4.1520 97.0000 1.0000
4.1600 97.0000 1.0000
4.1680 90.0000 1.0000
4.1760 112.0000 1.0000
4.1840 170.0000 1.0000
4.1920 189.0000 1.0000
4.2000 221.0000 1.0000
4.2080 318.0000 1.0000
4.2160 410.0000 1.0000
4.2240 436.0000 1.0000
4.2320 557.0000 1.0000
4.2400 588.0000 1.0000
4.2480 698.0000 1.0000
4.2560 780.0000 1.0000
4.2640 810.0000 1.0000
4.2720 883.0000 1.0000
4.2800 887.0000 1.0000
4.2880 952.0000 1.0000
4.2960 950.0000 1.0000
4.3040 891.0000 1.0000
4.3120 912.0000 1.0000
4.3200 925.0000 1.0000
4.3280 786.0000 1.0000
4.3360 849.0000 1.0000
4.3440 747.0000 1.0000
4.3520 690.0000 1.0000
4.3600 596.0000 1.0000
4.3680 498.0000 1.0000
4.3760 421.0000 1.0000
4.3840 386.0000 1.0000
4.3920 309.0000 1.0000
4.4000 243.0000 1.0000
4.4080 187.0000 1.0000
4.4160 160.0000 1.0000
4.4240 108.0000 1.0000
4.4320 104.0000 1.0000
4.4400 79.0000 1.0000
4.4480 97.0000 1.0000
4.4560 118.0000 1.0000
4.4640 128.0000 1.0000
4.4720 157.0000 1.0000
4.4800 195.0000 1.0000
4.4880 227.0000 1.0000
4.4960 273.0000 1.0000
4.5040 350.0000 1.0000
4.5120 417.0000 1.0000
4.5200 455.0000 1.0000
4.5280 486.0000 1.0000
4.5360 517.0000 1.0000
4.5440 632.0000 1.0000
4.5520 637.0000 1.0000
4.5600 643.0000 1.0000
4.5680 737.0000 1.0000
4.5760 666.0000 1.0000
4.5840 638.0000 1.0000
4.5920 658.0000 1.0000
4.6000 632.0000 1.0000
4.6080 654.0000 1.0000
4.6160 572.0000 1.0000
4.6240 517.0000 1.0000
4.6320 432.0000 1.0000
4.6400 445.0000 1.0000
4.6480 370.0000 1.0000
4.6560 325.0000 1.0000
4.6640 295.0000 1.0000
4.6720 210.0000 1.0000
4.6800 178.0000 1.0000
4.6880 157.0000 1.0000
4.6960 119.0000 1.0000
4.7040 99.0000 1.0000
4.7120 63.0000 1.0000
4.7200 97.0000 1.0000
4.7280 82.0000 1.0000
4.7360 95.0000 1.0000
4.7440 123.0000 1.0000
4.7520 127.0000 1.0000
4.7600 147.0000 1.0000
4.7680 195.0000 1.0000
4.7760 224.0000 1.0000
4.7840 279.0000 1.0000
4.7920 315.0000 1.0000
4.8000 353.0000 1.0000
4.8080 368.0000 1.0000
4.8160 432.0000 1.0000
4.8240 415.0000 1.0000
4.8320 408.0000 1.0000
4.8400 450.0000 1.0000
4.8480 455.0000 1.0000
4.8560 470.0000 1.0000
4.8640 451.0000 1.0000
4.8720 474.0000 1.0000
4.8800 438.0000 1.0000
4.8880 393.0000 1.0000
4.8960 397.0000 1.0000
4.9040 346.0000 1.0000
4.9120 277.0000 1.0000
4.9200 316.0000 1.0000
4.9280 251.0000 1.0000
4.9360 221.0000 1.0000
4.9440 199.0000 1.0000
4.9520 152.0000 1.0000
4.9600 136.0000 1.0000
4.9680 104.0000 1.0000
4.9760 101.0000 1.0000
4.9840 71.0000 1.0000
4.9920 68.0000 1.0000
5.0000 65.0000 1.0000
5.0080 70.0000 1.0000
5.0160 77.0000 1.0000
5.0240 103.0000 1.0000
5.0320 127.0000 1.0000
5.0400 152.0000 1.0000
5.0480 141.0000 1.0000
5.0560 172.0000 1.0000
5.0640 201.0000 1.0000
5.0720 210.0000 1.0000
5.0800 249.0000 1.0000
5.0880 287.0000 1.0000
5.0960 274.0000 1.0000
5.1040 299.0000 1.0000
5.1120 329.0000 1.0000
5.1200 311.0000 1.0000
5.1280 331.0000 1.0000
5.1360 312.0000 1.0000
5.1440 300.0000 1.0000
5.1520 294.0000 1.0000
5.1600 282.0000 1.0000
5.1680 260.0000 1.0000
5.1760 252.0000 1.0000
5.1840 230.0000 1.0000
5.1920 216.0000 1.0000
5.2000 181.0000 1.0000
5.2080 152.0000 1.0000
5.2160 121.0000 1.0000
5.2240 121.0000 1.0000
5.2320 105.0000 1.0000
5.2400 75.0000 1.0000
5.2480 64.0000 1.0000
5.2560 52.0000 1.0000
5.2640 51.0000 1.0000
5.2720 67.0000 1.0000
5.2800 42.0000 1.0000
5.2880 46.0000 1.0000
5.2960 63.0000 1.0000
5.3040 84.0000 1.0000
5.3120 93.0000 1.0000
5.3200 95.0000 1.0000
5.3280 104.0000 1.0000
5.3360 139.0000 1.0000
5.3440 125.0000 1.0000
5.3520 160.0000 1.0000
5.3600 177.0000 1.0000
5.3680 175.0000 1.0000
5.3760 179.0000 1.0000
5.3840 198.0000 1.0000
5.3920 201.0000 1.0000
5.4000 202.0000 1.0000
5.4080 229.0000 1.0000
5.4160 242.0000 1.0000
5.4240 201.0000 1.0000
5.4320 199.0000 1.0000
5.4400 178.0000 1.0000
5.4480 175.0000 1.0000
5.4560 161.0000 1.0000
5.4640 117.0000 1.0000
5.4720 144.0000 1.0000
5.4800 122.0000 1.0000
5.4880 106.0000 1.0000
5.4960 84.0000 1.0000
5.5040 71.0000 1.0000
5.5120 63.0000 1.0000
5.5200 49.0000 1.0000
5.5280 51.0000 1.0000
5.5360 42.0000 1.0000
5.5440 23.0000 1.0000
5.5520 30.0000 1.0000
5.5600 38.0000 1.0000
5.5680 38.0000 1.0000
5.5760 47.0000 1.0000
5.5840 58.0000 1.0000
5.5920 63.0000 1.0000
5.6000 77.0000 1.0000
5.6080 68.0000 1.0000
5.6160 96.0000 1.0000
5.6240 107.0000 1.0000
5.6320 104.0000 1.0000
5.6400 102.0000 1.0000
5.6480 125.0000 1.0000
5.6560 148.0000 1.0000
5.6640 131.0000 1.0000
5.6720 132.0000 1.0000
5.6800 132.0000 1.0000
5.6880 121.0000 1.0000
5.6960 121.0000 1.0000
5.7040 128.0000 1.0000
5.7120 145.0000 1.0000
5.7200 122.0000 1.0000
5.7280 91.0000 1.0000
5.7360 75.0000 1.0000
5.7440 83.0000 1.0000
5.7520 76.0000 1.0000
5.7600 56.0000 1.0000
5.7680 49.0000 1.0000
5.7760 43.0000 1.0000
5.7840 35.0000 1.0000
5.7920 35.0000 1.0000
5.8000 37.0000 1.0000
5.8080 28.0000 1.0000
5.8160 15.0000 1.0000
5.8240 23.0000 1.0000
5.8320 20.0000 1.0000
5.8400 15.0000 1.0000
5.8480 20.0000 1.0000
5.8560 31.0000 1.0000
5.8640 33.0000 1.0000
5.8720 38.0000 1.0000
5.8800 47.0000 1.0000
5.8880 49.0000 1.0000
5.8960 58.0000 1.0000
5.9040 69.0000 1.0000
5.9120 64.0000 1.0000
5.9200 62.0000 1.0000
5.9280 70.0000 1.0000
5.9360 73.0000 1.0000
5.9440 68.0000 1.0000
5.9520 78.0000 1.0000
5.9600 76.0000 1.0000
5.9680 71.0000 1.0000
5.9760 77.0000 1.0000
5.9840 74.0000 1.0000
5.9920 64.0000 1.0000
6.0000 51.0000 1.0000
*RAS_INT_END
*RAS_TEMPERATURE_START
*RAS_TEMPERATURE_END
*RAS_DATA_END