File: 20220926_XRR/20210729-1-5 2/20210729-3_pre.ras
*RAS_DATA_START
*RAS_HEADER_START
*DISP_FMT_X "%.3f"
*DISP_FMT_Y "%.0f"
*DISP_FULLSCALE "35454761.4000000060"
*DISP_LINE_COLOR "255.0000000000"
*DISP_LINE_STYLE "0.0000000000"
*DISP_LINE_WIDTH "0.2500000000"
*DISP_NOTE "測定データ-1"
*DISP_OFFSET_Y "0.0000000000"
*DISP_PEAKSEARCH_UNIT_Y "cps"
*DISP_RANGE_BOTTOM "0.0100000000"
*DISP_RANGE_LEFT "0.0000000000"
*DISP_RANGE_LOGCUTOFF "0.0100000000"
*DISP_RANGE_RIGHT "6.0000000000"
*DISP_RANGE_TOP "35454761.4000000060"
*DISP_SCALE_MODE_Y "2.0000000000"
*DISP_TAB_NAME "2θ/ω"
*DISP_TITLE_Y "強度"
*DISP_UNIT_Y "cps"
*DISP_WINDOW_NAME "MSG_MACROENGINE"
*FILE_COMMENT " "
*FILE_MD5 ""
*FILE_MEMO " "
*FILE_OPERATOR "User1"
*FILE_PART_ID "MEAS_KHP2_00055"
*FILE_SAMPLE "1V090203 Fe35h VSM"
*FILE_TYPE "RAS_RAW"
*FILE_USERGROUP "システムマネージャ"
*FILE_VERSION "1.0000000000"
*HW_ATTACHMENT_ID "ATT0022"
*HW_ATTACHMENT_NAME "RxRy|RxRy"
*HW_COUNTER_ID-0 "CUT0021"
*HW_COUNTER_ID-1 "CUT0020"
*HW_COUNTER_ID-2 ""
*HW_COUNTER_ID-3 "CSL0021"
*HW_COUNTER_ID-4 "CMC0021"
*HW_COUNTER_NAME-0 "SC-70|SC-70"
*HW_COUNTER_NAME-1 "None|None"
*HW_COUNTER_NAME-2 ""
*HW_COUNTER_NAME-3 "BBM|BBM"
*HW_COUNTER_NAME-4 "検出器モノクロメータ|Detector monochromator"
*HW_COUNTER_SELECT_NAME "SC-70|SC-70"
*HW_ECP_HV "626.0000000000"
*HW_ECP_HV_UNIT "V"
*HW_GONIOMETER_ID "GON0024"
*HW_GONIOMETER_NAME "SmartLab(In-plane)|SmartLab(In-plane)"
*HW_GONIOMETER_RADIUS-0 "90.0"
*HW_GONIOMETER_RADIUS-1 "114.0"
*HW_GONIOMETER_RADIUS-2 "190.0"
*HW_GONIOMETER_RADIUS-3 "300.0"
*HW_GONIOMETER_RADIUS-4 "187.0"
*HW_GONIOMETER_RADIUS-5 "300.0"
*HW_GONIOMETER_RADIUS-6 "113.0"
*HW_GONIOMETER_RADIUS-7 "331.0"
*HW_I_OPT_ID-0 "CBO0021"
*HW_I_OPT_ID-1 "ICR0021"
*HW_I_OPT_ID-2 "ISL0021"
*HW_I_OPT_ID-3 "ISO0021"
*HW_I_OPT_ID-4 "IAD0021"
*HW_I_OPT_ID-5 "IPR0001"
*HW_I_OPT_NAME-0 "CBOユニット|CBO unit"
*HW_I_OPT_NAME-1 "標準入射光学ユニット|Standard incident optical unit"
*HW_I_OPT_NAME-2 "標準入射スリットボックス|Standard incident slit box"
*HW_I_OPT_NAME-3 "入射平行スリット|Incident parallel slit"
*HW_I_OPT_NAME-4 "長手制限スリット|Length limiting slit"
*HW_I_OPT_NAME-5 "None|None"
*HW_R_ATTENUATER_AUTOMODE "1"
*HW_R_OPT_ID-0 "RSS0021"
*HW_R_OPT_ID-1 "RCR0022"
*HW_R_OPT_ID-2 "RSO0021"
*HW_R_OPT_ID-3 "RRS0021"
*HW_R_OPT_ID-4 "ATN0021"
*HW_R_OPT_ID-5 "RFL0021"
*HW_R_OPT_ID-6 "RAD0021"
*HW_R_OPT_NAME-0 "標準受光スリットボックス1|Standard receiving slit box # 1"
*HW_R_OPT_NAME-1 "標準受光光学ユニット1|Standard receiving unit # 1"
*HW_R_OPT_NAME-2 "標準受光光学ユニット2|Standard receiving optical unit # 2"
*HW_R_OPT_NAME-3 "標準受光スリットボックス2|Standard receiving slit box # 2"
*HW_R_OPT_NAME-4 "標準アッテネータ|Standard Attenuator"
*HW_R_OPT_NAME-5 "Cu Kβ|Cu K-beta"
*HW_R_OPT_NAME-6 "調整用受光スリット|Alignment receiving slit"
*HW_SAMPLE_HOLDER_ID "SMP0021"
*HW_SAMPLE_HOLDER_NAME "χφZクレードル|Chi phi Z cradle"
*HW_XG_CURRENT_MAX "200"
*HW_XG_CURRENT_MIN "10"
*HW_XG_CURRENT_RESOLUTION "1"
*HW_XG_CURRENT_UNIT "mA"
*HW_XG_FOCUS "0.4mm x 8mm"
*HW_XG_FOCUS_TYPE "Normal"
*HW_XG_ID "1700"
*HW_XG_NAME "9kW 開放管(45kV 200mA ID:1700)|9kW Rotating anode(45kV 200mA ID:1700)"
*HW_XG_TARGET_ATOMIC_NUMBER "29.0000000000"
*HW_XG_TARGET_NAME "Cu"
*HW_XG_TYPE "Rota"
*HW_XG_VOLTAGE_MAX "45"
*HW_XG_VOLTAGE_MIN "20"
*HW_XG_VOLTAGE_RESOLUTION "1"
*HW_XG_VOLTAGE_UNIT "kV"
*HW_XG_WATT_MAX "9"
*HW_XG_WATT_UNIT "kW"
*HW_XG_WAVE_LENGTH_ALPHA1 "1.540593"
*HW_XG_WAVE_LENGTH_ALPHA2 "1.544414"
*HW_XG_WAVE_LENGTH_BETA "1.392250"
*MEAS_COND_AXIS_NAME-0 "2θ/θ"
*MEAS_COND_AXIS_NAME-1 "2θ"
*MEAS_COND_AXIS_NAME-2 "ω"
*MEAS_COND_AXIS_NAME-3 "χ"
*MEAS_COND_AXIS_NAME-4 "φ"
*MEAS_COND_AXIS_NAME-5 "Z"
*MEAS_COND_AXIS_NAME-6 "Rx"
*MEAS_COND_AXIS_NAME-7 "Ry"
*MEAS_COND_AXIS_NAME-8 "2θ/ω"
*MEAS_COND_AXIS_NAME-9 "2θχ"
*MEAS_COND_AXIS_NAME-10 "2θχ/φ"
*MEAS_COND_AXIS_NAME-11 "α"
*MEAS_COND_AXIS_NAME-12 "β"
*MEAS_COND_AXIS_NAME-13 "θs"
*MEAS_COND_AXIS_NAME-14 "θd"
*MEAS_COND_AXIS_NAME-15 "Ts"
*MEAS_COND_AXIS_NAME-16 "CBO選択スリット"
*MEAS_COND_AXIS_NAME-17 "M"
*MEAS_COND_AXIS_NAME-18 "入射平行スリット"
*MEAS_COND_AXIS_NAME-19 "入射スリット"
*MEAS_COND_AXIS_NAME-20 ""
*MEAS_COND_AXIS_NAME-21 "Zs"
*MEAS_COND_AXIS_NAME-22 "入射光学素子"
*MEAS_COND_AXIS_NAME-23 "ωm"
*MEAS_COND_AXIS_NAME-24 "長手制限スリット"
*MEAS_COND_AXIS_NAME-25 "センタースリット"
*MEAS_COND_AXIS_NAME-26 "フィルター"
*MEAS_COND_AXIS_NAME-27 "受光スリット1"
*MEAS_COND_AXIS_NAME-28 "受光スリット2"
*MEAS_COND_AXIS_NAME-29 "受光光学素子"
*MEAS_COND_AXIS_NAME-30 "受光平行スリット"
*MEAS_COND_AXIS_NAME-31 "調整用受光スリット"
*MEAS_COND_AXIS_NAME-32 ""
*MEAS_COND_AXIS_NAME-33 ""
*MEAS_COND_AXIS_NAME-34 "Zd"
*MEAS_COND_AXIS_NAME-35 "アッテネータ"
*MEAS_COND_AXIS_NAME-36 "検出器モノクロメータ"
*MEAS_COND_AXIS_NAME-37 "モノクロメータスリット"
*MEAS_COND_AXIS_NAME-38 "2θB"
*MEAS_COND_AXIS_NAME-39 ""
*MEAS_COND_AXIS_NAME-40 ""
*MEAS_COND_AXIS_NAME-41 "プライマリビーム"
*MEAS_COND_AXIS_NAME-42 "HV"
*MEAS_COND_AXIS_NAME-43 "PHA"
*MEAS_COND_AXIS_NAME_INTERNAL-0 "TwoThetaTheta"
*MEAS_COND_AXIS_NAME_INTERNAL-1 "TwoTheta"
*MEAS_COND_AXIS_NAME_INTERNAL-2 "Omega"
*MEAS_COND_AXIS_NAME_INTERNAL-3 "Chi"
*MEAS_COND_AXIS_NAME_INTERNAL-4 "Phi"
*MEAS_COND_AXIS_NAME_INTERNAL-5 "Z"
*MEAS_COND_AXIS_NAME_INTERNAL-6 "Rx"
*MEAS_COND_AXIS_NAME_INTERNAL-7 "Ry"
*MEAS_COND_AXIS_NAME_INTERNAL-8 "TwoThetaOmega"
*MEAS_COND_AXIS_NAME_INTERNAL-9 "TwoThetaChi"
*MEAS_COND_AXIS_NAME_INTERNAL-10 "TwoThetaChiPhi"
*MEAS_COND_AXIS_NAME_INTERNAL-11 "Alpha"
*MEAS_COND_AXIS_NAME_INTERNAL-12 "Beta"
*MEAS_COND_AXIS_NAME_INTERNAL-13 "ThetaS"
*MEAS_COND_AXIS_NAME_INTERNAL-14 "ThetaD"
*MEAS_COND_AXIS_NAME_INTERNAL-15 "Ts"
*MEAS_COND_AXIS_NAME_INTERNAL-16 "CBO"
*MEAS_COND_AXIS_NAME_INTERNAL-17 "CBO-M"
*MEAS_COND_AXIS_NAME_INTERNAL-18 "IncidentSollerSlit"
*MEAS_COND_AXIS_NAME_INTERNAL-19 "IncidentSlitBox"
*MEAS_COND_AXIS_NAME_INTERNAL-20 "IncidentSlitBox-_Axis"
*MEAS_COND_AXIS_NAME_INTERNAL-21 "Zs"
*MEAS_COND_AXIS_NAME_INTERNAL-22 "IncidentMonochromator"
*MEAS_COND_AXIS_NAME_INTERNAL-23 "IncidentMonochromator-OmegaM"
*MEAS_COND_AXIS_NAME_INTERNAL-24 "IncidentAxdSlit"
*MEAS_COND_AXIS_NAME_INTERNAL-25 "CenterSlit"
*MEAS_COND_AXIS_NAME_INTERNAL-26 "Filter"
*MEAS_COND_AXIS_NAME_INTERNAL-27 "ReceivingSlitBox1"
*MEAS_COND_AXIS_NAME_INTERNAL-28 "ReceivingSlitBox2"
*MEAS_COND_AXIS_NAME_INTERNAL-29 "ReceivingOptics"
*MEAS_COND_AXIS_NAME_INTERNAL-30 "ReceivingSollerSlit"
*MEAS_COND_AXIS_NAME_INTERNAL-31 "ReceivingAxdSlit"
*MEAS_COND_AXIS_NAME_INTERNAL-32 "ReceivingSlitBox1-_Axis"
*MEAS_COND_AXIS_NAME_INTERNAL-33 "ReceivingSlitBox2-_Axis"
*MEAS_COND_AXIS_NAME_INTERNAL-34 "ReceivingSlitBox2-Zd"
*MEAS_COND_AXIS_NAME_INTERNAL-35 "Attenuator"
*MEAS_COND_AXIS_NAME_INTERNAL-36 "CounterMonochromator"
*MEAS_COND_AXIS_NAME_INTERNAL-37 "CounterSlit"
*MEAS_COND_AXIS_NAME_INTERNAL-38 "TwoThetaB"
*MEAS_COND_AXIS_NAME_INTERNAL-39 "AlphaR"
*MEAS_COND_AXIS_NAME_INTERNAL-40 "BetaR"
*MEAS_COND_AXIS_NAME_INTERNAL-41 "IncidentPrimary"
*MEAS_COND_AXIS_NAME_INTERNAL-42 "HV"
*MEAS_COND_AXIS_NAME_INTERNAL-43 "PHA"
*MEAS_COND_AXIS_NAME_MAGICNO-0 "83951616.0000000000"
*MEAS_COND_AXIS_NAME_MAGICNO-1 "268632064.0000000000"
*MEAS_COND_AXIS_NAME_MAGICNO-2 "268500992.0000000000"
*MEAS_COND_AXIS_NAME_MAGICNO-3 "268500992.0000000000"
*MEAS_COND_AXIS_NAME_MAGICNO-4 "268500992.0000000000"
*MEAS_COND_AXIS_NAME_MAGICNO-5 "285278208.0000000000"
*MEAS_COND_AXIS_NAME_MAGICNO-6 "285278208.0000000000"
*MEAS_COND_AXIS_NAME_MAGICNO-7 "285278208.0000000000"
*MEAS_COND_AXIS_NAME_MAGICNO-8 "83951616.0000000000"
*MEAS_COND_AXIS_NAME_MAGICNO-9 "268632064.0000000000"
*MEAS_COND_AXIS_NAME_MAGICNO-10 "83951616.0000000000"
*MEAS_COND_AXIS_NAME_MAGICNO-11 "17039360.0000000000"
*MEAS_COND_AXIS_NAME_MAGICNO-12 "17039360.0000000000"
*MEAS_COND_AXIS_NAME_MAGICNO-13 "131072.0000000000"
*MEAS_COND_AXIS_NAME_MAGICNO-14 "131072.0000000000"
*MEAS_COND_AXIS_NAME_MAGICNO-15 "318898176.0000000000"
*MEAS_COND_AXIS_NAME_MAGICNO-16 "20971521.0000000000"
*MEAS_COND_AXIS_NAME_MAGICNO-17 "285343744.0000000000"
*MEAS_COND_AXIS_NAME_MAGICNO-18 "20971521.0000000000"
*MEAS_COND_AXIS_NAME_MAGICNO-19 "22020097.0000000000"
*MEAS_COND_AXIS_NAME_MAGICNO-20 "25165824.0000000000"
*MEAS_COND_AXIS_NAME_MAGICNO-21 "318898176.0000000000"
*MEAS_COND_AXIS_NAME_MAGICNO-22 "20971521.0000000000"
*MEAS_COND_AXIS_NAME_MAGICNO-23 "285343744.0000000000"
*MEAS_COND_AXIS_NAME_MAGICNO-24 "20971521.0000000000"
*MEAS_COND_AXIS_NAME_MAGICNO-25 "20971521.0000000000"
*MEAS_COND_AXIS_NAME_MAGICNO-26 "20971521.0000000000"
*MEAS_COND_AXIS_NAME_MAGICNO-27 "23068673.0000000000"
*MEAS_COND_AXIS_NAME_MAGICNO-28 "23068673.0000000000"
*MEAS_COND_AXIS_NAME_MAGICNO-29 "20971521.0000000000"
*MEAS_COND_AXIS_NAME_MAGICNO-30 "20971521.0000000000"
*MEAS_COND_AXIS_NAME_MAGICNO-31 "20971521.0000000000"
*MEAS_COND_AXIS_NAME_MAGICNO-32 "25165824.0000000000"
*MEAS_COND_AXIS_NAME_MAGICNO-33 "25165824.0000000000"
*MEAS_COND_AXIS_NAME_MAGICNO-34 "285343744.0000000000"
*MEAS_COND_AXIS_NAME_MAGICNO-35 "17301505.0000000000"
*MEAS_COND_AXIS_NAME_MAGICNO-36 "20971521.0000000000"
*MEAS_COND_AXIS_NAME_MAGICNO-37 "20971521.0000000000"
*MEAS_COND_AXIS_NAME_MAGICNO-38 "17039360.0000000000"
*MEAS_COND_AXIS_NAME_MAGICNO-39 "8388608.0000000000"
*MEAS_COND_AXIS_NAME_MAGICNO-40 "8388608.0000000000"
*MEAS_COND_AXIS_NAME_MAGICNO-41 "20971521.0000000000"
*MEAS_COND_AXIS_NAME_MAGICNO-42 "0.0000000000"
*MEAS_COND_AXIS_NAME_MAGICNO-43 "0.0000000000"
*MEAS_COND_AXIS_OFFSET-0 "-"
*MEAS_COND_AXIS_OFFSET-1 "1.2633000000"
*MEAS_COND_AXIS_OFFSET-2 "1.5249000000"
*MEAS_COND_AXIS_OFFSET-3 "0.0000000000"
*MEAS_COND_AXIS_OFFSET-4 "0.0000000000"
*MEAS_COND_AXIS_OFFSET-5 "-"
*MEAS_COND_AXIS_OFFSET-6 "-"
*MEAS_COND_AXIS_OFFSET-7 "-"
*MEAS_COND_AXIS_OFFSET-8 "-"
*MEAS_COND_AXIS_OFFSET-9 "0.0000000000"
*MEAS_COND_AXIS_OFFSET-10 "-"
*MEAS_COND_AXIS_OFFSET-11 "-"
*MEAS_COND_AXIS_OFFSET-12 "-"
*MEAS_COND_AXIS_OFFSET-13 "1.5249000000"
*MEAS_COND_AXIS_OFFSET-14 "-0.2616000000"
*MEAS_COND_AXIS_OFFSET-15 "-"
*MEAS_COND_AXIS_OFFSET-16 "-"
*MEAS_COND_AXIS_OFFSET-17 "-"
*MEAS_COND_AXIS_OFFSET-18 "-"
*MEAS_COND_AXIS_OFFSET-19 "-"
*MEAS_COND_AXIS_OFFSET-20 "-"
*MEAS_COND_AXIS_OFFSET-21 "-"
*MEAS_COND_AXIS_OFFSET-22 "-"
*MEAS_COND_AXIS_OFFSET-23 "-"
*MEAS_COND_AXIS_OFFSET-24 "-"
*MEAS_COND_AXIS_OFFSET-25 "-"
*MEAS_COND_AXIS_OFFSET-26 "-"
*MEAS_COND_AXIS_OFFSET-27 "-"
*MEAS_COND_AXIS_OFFSET-28 "-"
*MEAS_COND_AXIS_OFFSET-29 "-"
*MEAS_COND_AXIS_OFFSET-30 "-"
*MEAS_COND_AXIS_OFFSET-31 "-"
*MEAS_COND_AXIS_OFFSET-32 "-"
*MEAS_COND_AXIS_OFFSET-33 "-"
*MEAS_COND_AXIS_OFFSET-34 "-"
*MEAS_COND_AXIS_OFFSET-35 "-"
*MEAS_COND_AXIS_OFFSET-36 "-"
*MEAS_COND_AXIS_OFFSET-37 "-"
*MEAS_COND_AXIS_OFFSET-38 "-"
*MEAS_COND_AXIS_OFFSET-39 "0.0000000000"
*MEAS_COND_AXIS_OFFSET-40 "0.0000000000"
*MEAS_COND_AXIS_OFFSET-41 "-"
*MEAS_COND_AXIS_OFFSET-42 "-"
*MEAS_COND_AXIS_OFFSET-43 "-"
*MEAS_COND_AXIS_POSITION-0 "-0.0020000000"
*MEAS_COND_AXIS_POSITION-1 "-0.0020000000"
*MEAS_COND_AXIS_POSITION-2 "-0.0010000000"
*MEAS_COND_AXIS_POSITION-3 "0.2860000000"
*MEAS_COND_AXIS_POSITION-4 "0.0000000000"
*MEAS_COND_AXIS_POSITION-5 "-0.3046000000"
*MEAS_COND_AXIS_POSITION-6 "0.0000000000"
*MEAS_COND_AXIS_POSITION-7 "0.0000000000"
*MEAS_COND_AXIS_POSITION-8 "-0.0020000000"
*MEAS_COND_AXIS_POSITION-9 "0.0000000000"
*MEAS_COND_AXIS_POSITION-10 "0.0000000000"
*MEAS_COND_AXIS_POSITION-11 "-89.9800000000"
*MEAS_COND_AXIS_POSITION-12 "0.0000000000"
*MEAS_COND_AXIS_POSITION-13 "-0.0010000000"
*MEAS_COND_AXIS_POSITION-14 "-0.0010000000"
*MEAS_COND_AXIS_POSITION-15 "-6.2220600000"
*MEAS_COND_AXIS_POSITION-16 "PB"
*MEAS_COND_AXIS_POSITION-17 "0.0000000000"
*MEAS_COND_AXIS_POSITION-18 "Soller_slit_open_s"
*MEAS_COND_AXIS_POSITION-19 "0.100mm"
*MEAS_COND_AXIS_POSITION-20 "0.1000000000"
*MEAS_COND_AXIS_POSITION-21 "-1.7509400000"
*MEAS_COND_AXIS_POSITION-22 "Ge(220)x2"
*MEAS_COND_AXIS_POSITION-23 "0.0000000000"
*MEAS_COND_AXIS_POSITION-24 "5.0mm"
*MEAS_COND_AXIS_POSITION-25 "None"
*MEAS_COND_AXIS_POSITION-26 "None"
*MEAS_COND_AXIS_POSITION-27 "0.200mm"
*MEAS_COND_AXIS_POSITION-28 "0.200mm"
*MEAS_COND_AXIS_POSITION-29 "PSA_open"
*MEAS_COND_AXIS_POSITION-30 "Soller_slit_5.0deg"
*MEAS_COND_AXIS_POSITION-31 "None"
*MEAS_COND_AXIS_POSITION-32 "0.2000000000"
*MEAS_COND_AXIS_POSITION-33 "0.2000000000"
*MEAS_COND_AXIS_POSITION-34 "0.2740600000"
*MEAS_COND_AXIS_POSITION-35 "1/10000"
*MEAS_COND_AXIS_POSITION-36 "None"
*MEAS_COND_AXIS_POSITION-37 "None"
*MEAS_COND_AXIS_POSITION-38 "0.0020000000"
*MEAS_COND_AXIS_POSITION-39 "-0.1120000000"
*MEAS_COND_AXIS_POSITION-40 "0.0000000000"
*MEAS_COND_AXIS_POSITION-41 "None"
*MEAS_COND_AXIS_POSITION-42 "626.0000000000"
*MEAS_COND_AXIS_POSITION-43 "603.7500000000"
*MEAS_COND_AXIS_UNIT-0 "deg"
*MEAS_COND_AXIS_UNIT-1 "deg"
*MEAS_COND_AXIS_UNIT-2 "deg"
*MEAS_COND_AXIS_UNIT-3 "deg"
*MEAS_COND_AXIS_UNIT-4 "deg"
*MEAS_COND_AXIS_UNIT-5 "mm"
*MEAS_COND_AXIS_UNIT-6 "deg"
*MEAS_COND_AXIS_UNIT-7 "deg"
*MEAS_COND_AXIS_UNIT-8 "deg"
*MEAS_COND_AXIS_UNIT-9 "deg"
*MEAS_COND_AXIS_UNIT-10 "deg"
*MEAS_COND_AXIS_UNIT-11 "deg"
*MEAS_COND_AXIS_UNIT-12 "deg"
*MEAS_COND_AXIS_UNIT-13 "deg"
*MEAS_COND_AXIS_UNIT-14 "deg"
*MEAS_COND_AXIS_UNIT-15 "mm"
*MEAS_COND_AXIS_UNIT-16 ""
*MEAS_COND_AXIS_UNIT-17 "pulse"
*MEAS_COND_AXIS_UNIT-18 ""
*MEAS_COND_AXIS_UNIT-19 ""
*MEAS_COND_AXIS_UNIT-20 "mm"
*MEAS_COND_AXIS_UNIT-21 "mm"
*MEAS_COND_AXIS_UNIT-22 ""
*MEAS_COND_AXIS_UNIT-23 "pulse"
*MEAS_COND_AXIS_UNIT-24 ""
*MEAS_COND_AXIS_UNIT-25 ""
*MEAS_COND_AXIS_UNIT-26 ""
*MEAS_COND_AXIS_UNIT-27 ""
*MEAS_COND_AXIS_UNIT-28 ""
*MEAS_COND_AXIS_UNIT-29 ""
*MEAS_COND_AXIS_UNIT-30 ""
*MEAS_COND_AXIS_UNIT-31 ""
*MEAS_COND_AXIS_UNIT-32 "mm"
*MEAS_COND_AXIS_UNIT-33 "mm"
*MEAS_COND_AXIS_UNIT-34 "mm"
*MEAS_COND_AXIS_UNIT-35 ""
*MEAS_COND_AXIS_UNIT-36 ""
*MEAS_COND_AXIS_UNIT-37 ""
*MEAS_COND_AXIS_UNIT-38 "deg"
*MEAS_COND_AXIS_UNIT-39 "deg"
*MEAS_COND_AXIS_UNIT-40 "deg"
*MEAS_COND_AXIS_UNIT-41 ""
*MEAS_COND_AXIS_UNIT-42 "V"
*MEAS_COND_AXIS_UNIT-43 "mV"
*MEAS_COND_COUNTER_CNTLOSS_CORR "1.0000000000"
*MEAS_COND_COUNTER_PHABASE "603.7500000000"
*MEAS_COND_COUNTER_PHAWINDOW "855.0000000000"
*MEAS_COND_COUNTER_PHA_UNIT "mV"
*MEAS_COND_COUNTER_TAUDIFF "0.1777010000"
*MEAS_COND_COUNTER_TAUINT "0.6912320000"
*MEAS_COND_IRRADIATION_MODE "OFF"
*MEAS_COND_IRRADIATION_WIDTH ""
*MEAS_COND_OPT_ATTR "高分解能平行ビームGe(220)x2/受光スリット"
*MEAS_COND_OPT_NAME "@高分解能PB-Ge(220)x2"
*MEAS_COND_UNSYMMETRIC_MODE "OFF"
*MEAS_COND_XG_CURRENT "200.0000000000"
*MEAS_COND_XG_VOLTAGE "45.0000000000"
*MEAS_COND_XG_WAVE_TYPE "Ka1"
*MEAS_DATA_COUNT "1501.0000000000"
*MEAS_SCAN_AXIS_X "2θ/ω"
*MEAS_SCAN_AXIS_X_INTERNAL "TwoThetaOmega"
*MEAS_SCAN_END_TIME "07/29/21 10:48:57"
*MEAS_SCAN_MODE "CONTINUOUS"
*MEAS_SCAN_MONITOR "0"
*MEAS_SCAN_RESOLUTION_X "0.0002"
*MEAS_SCAN_SPEED "3.000000"
*MEAS_SCAN_SPEED_UNIT "deg/min"
*MEAS_SCAN_SPEED_USER "3.0000"
*MEAS_SCAN_START "0.0000000000"
*MEAS_SCAN_START_TIME "07/29/21 10:46:36"
*MEAS_SCAN_STEP "0.0040000000"
*MEAS_SCAN_STOP "6.0000000000"
*MEAS_SCAN_UNIT_X "deg"
*MEAS_SCAN_UNIT_Y "counts"
*RAS_HEADER_END
*RAS_INT_START
0.0000 2822.0000 837.5800
0.0080 2713.9998 837.5800
0.0160 2346.0000 837.5800
0.0240 1440.0000 837.5800
0.0320 487.0000 837.5800
0.0400 1951.0000 53.5042
0.0480 681.0000 53.5042
0.0560 403.0000 53.5042
0.0640 309.0000 53.5042
0.0720 305.0000 53.5042
0.0800 304.0000 53.5042
0.0880 311.0000 53.5042
0.0960 317.0000 53.5042
0.1040 385.0000 53.5042
0.1120 382.0000 53.5042
0.1200 443.0000 53.5042
0.1280 438.0000 53.5042
0.1360 484.0000 53.5042
0.1440 440.0000 53.5042
0.1520 516.0000 53.5042
0.1600 577.0000 53.5042
0.1680 515.0000 53.5042
0.1760 558.0000 53.5042
0.1840 605.0000 53.5042
0.1920 597.0000 53.5042
0.2000 636.0000 53.5042
0.2080 697.9999 53.5042
0.2160 710.0000 53.5042
0.2240 747.0000 53.5042
0.2320 762.0000 53.5042
0.2400 788.0000 53.5042
0.2480 802.0000 53.5042
0.2560 860.0000 53.5042
0.2640 915.0000 53.5042
0.2720 909.0000 53.5042
0.2800 930.0000 53.5042
0.2880 951.0001 53.5042
0.2960 970.0000 53.5042
0.3040 966.0000 53.5042
0.3120 1032.0000 53.5042
0.3200 1018.0001 53.5042
0.3280 1013.0000 53.5042
0.3360 1124.0000 53.5042
0.3440 1135.0000 53.5042
0.3520 1093.0000 53.5042
0.3600 1168.0000 53.5042
0.3680 1218.0000 53.5042
0.3760 1201.0000 53.5042
0.3840 1255.0000 53.5042
0.3920 1195.0000 53.5042
0.4000 1260.0000 53.5042
0.4080 1281.0000 53.5042
0.4160 1268.0000 53.5042
0.4240 1322.0000 53.5042
0.4320 1311.0000 53.5042
0.4400 1328.0000 53.5042
0.4480 1383.0001 53.5042
0.4560 1362.0000 53.5042
0.4640 1458.0000 53.5042
0.4720 1414.0000 53.5042
0.4800 1392.0000 53.5042
0.4880 1454.0000 53.5042
0.4960 1357.0001 53.5042
0.5040 1519.0000 53.5042
0.5120 1439.0000 53.5042
0.5200 1525.0000 53.5042
0.5280 1542.0000 53.5042
0.5360 1547.0000 53.5042
0.5440 1467.0000 53.5042
0.5520 1563.0000 53.5042
0.5600 1527.0000 53.5042
0.5680 1510.0000 53.5042
0.5760 1491.0001 53.5042
0.5840 1526.0000 53.5042
0.5920 1606.0000 53.5042
0.6000 1491.0001 53.5042
0.6080 1514.0000 53.5042
0.6160 1557.0000 53.5042
0.6240 1527.9999 53.5042
0.6320 1469.0000 53.5042
0.6400 1568.0000 53.5042
0.6480 1475.9999 53.5042
0.6560 1455.0000 53.5042
0.6640 1408.0000 53.5042
0.6720 1400.0000 53.5042
0.6800 1439.0000 53.5042
0.6880 1308.0000 53.5042
0.6960 1370.0001 53.5042
0.7040 1223.0000 53.5042
0.7120 1161.0000 53.5042
0.7200 1167.0000 53.5042
0.7280 1046.0000 53.5042
0.7360 963.9999 53.5042
0.7440 966.0000 53.5042
0.7520 915.0000 53.5042
0.7600 781.0000 53.5042
0.7680 709.0000 53.5042
0.7760 647.0000 53.5042
0.7840 562.0000 53.5042
0.7920 465.0000 53.5042
0.8000 423.0000 53.5042
0.8080 371.0000 53.5042
0.8160 356.0000 53.5042
0.8240 278.0000 53.5042
0.8320 278.0000 53.5042
0.8400 238.0000 53.5042
0.8480 214.0000 53.5042
0.8560 11228.0000 1.0000
0.8640 10119.0000 1.0000
0.8720 9258.0000 1.0000
0.8800 8105.0000 1.0000
0.8880 7370.0000 1.0000
0.8960 6822.0000 1.0000
0.9040 6146.0000 1.0000
0.9120 5614.0000 1.0000
0.9200 5143.0000 1.0000
0.9280 4828.0000 1.0000
0.9360 4357.0000 1.0000
0.9440 3910.0000 1.0000
0.9520 3637.0000 1.0000
0.9600 3240.0000 1.0000
0.9680 2998.0000 1.0000
0.9760 2825.0000 1.0000
0.9840 2660.0000 1.0000
0.9920 2358.0000 1.0000
1.0000 2164.0000 1.0000
1.0080 2035.0000 1.0000
1.0160 1804.0000 1.0000
1.0240 1766.0000 1.0000
1.0320 1542.0000 1.0000
1.0400 1559.0000 1.0000
1.0480 1396.0000 1.0000
1.0560 1281.0000 1.0000
1.0640 1188.0000 1.0000
1.0720 1058.0000 1.0000
1.0800 1025.0000 1.0000
1.0880 965.0000 1.0000
1.0960 847.0000 1.0000
1.1040 783.0000 1.0000
1.1120 714.0000 1.0000
1.1200 684.0000 1.0000
1.1280 591.0000 1.0000
1.1360 559.0000 1.0000
1.1440 527.0000 1.0000
1.1520 467.0000 1.0000
1.1600 430.0000 1.0000
1.1680 407.0000 1.0000
1.1760 356.0000 1.0000
1.1840 349.0000 1.0000
1.1920 302.0000 1.0000
1.2000 261.0000 1.0000
1.2080 298.0000 1.0000
1.2160 280.0000 1.0000
1.2240 186.0000 1.0000
1.2320 185.0000 1.0000
1.2400 190.0000 1.0000
1.2480 165.0000 1.0000
1.2560 151.0000 1.0000
1.2640 136.0000 1.0000
1.2720 139.0000 1.0000
1.2800 114.0000 1.0000
1.2880 115.0000 1.0000
1.2960 103.0000 1.0000
1.3040 92.0000 1.0000
1.3120 88.0000 1.0000
1.3200 71.0000 1.0000
1.3280 56.0000 1.0000
1.3360 73.0000 1.0000
1.3440 58.0000 1.0000
1.3520 56.0000 1.0000
1.3600 55.0000 1.0000
1.3680 48.0000 1.0000
1.3760 42.0000 1.0000
1.3840 36.0000 1.0000
1.3920 37.0000 1.0000
1.4000 27.0000 1.0000
1.4080 19.0000 1.0000
1.4160 30.0000 1.0000
1.4240 17.0000 1.0000
1.4320 21.0000 1.0000
1.4400 13.0000 1.0000
1.4480 16.0000 1.0000
1.4560 10.0000 1.0000
1.4640 12.0000 1.0000
1.4720 8.0000 1.0000
1.4800 13.0000 1.0000
1.4880 5.0000 1.0000
1.4960 12.0000 1.0000
1.5040 9.0000 1.0000
1.5120 2.0000 1.0000
1.5200 4.0000 1.0000
1.5280 10.0000 1.0000
1.5360 4.0000 1.0000
1.5440 7.0000 1.0000
1.5520 9.0000 1.0000
1.5600 4.0000 1.0000
1.5680 3.0000 1.0000
1.5760 1.0000 1.0000
1.5840 6.0000 1.0000
1.5920 6.0000 1.0000
1.6000 3.0000 1.0000
1.6080 3.0000 1.0000
1.6160 0.0000 1.0000
1.6240 5.0000 1.0000
1.6320 1.0000 1.0000
1.6400 4.0000 1.0000
1.6480 4.0000 1.0000
1.6560 4.0000 1.0000
1.6640 3.0000 1.0000
1.6720 4.0000 1.0000
1.6800 2.0000 1.0000
1.6880 6.0000 1.0000
1.6960 8.0000 1.0000
1.7040 4.0000 1.0000
1.7120 3.0000 1.0000
1.7200 3.0000 1.0000
1.7280 3.0000 1.0000
1.7360 7.0000 1.0000
1.7440 3.0000 1.0000
1.7520 6.0000 1.0000
1.7600 6.0000 1.0000
1.7680 6.0000 1.0000
1.7760 5.0000 1.0000
1.7840 3.0000 1.0000
1.7920 1.0000 1.0000
1.8000 3.0000 1.0000
1.8080 7.0000 1.0000
1.8160 8.0000 1.0000
1.8240 3.0000 1.0000
1.8320 4.0000 1.0000
1.8400 3.0000 1.0000
1.8480 7.0000 1.0000
1.8560 2.0000 1.0000
1.8640 4.0000 1.0000
1.8720 11.0000 1.0000
1.8800 7.0000 1.0000
1.8880 6.0000 1.0000
1.8960 6.0000 1.0000
1.9040 6.0000 1.0000
1.9120 6.0000 1.0000
1.9200 5.0000 1.0000
1.9280 10.0000 1.0000
1.9360 6.0000 1.0000
1.9440 3.0000 1.0000
1.9520 5.0000 1.0000
1.9600 6.0000 1.0000
1.9680 5.0000 1.0000
1.9760 6.0000 1.0000
1.9840 6.0000 1.0000
1.9920 7.0000 1.0000
2.0000 2.0000 1.0000
2.0080 6.0000 1.0000
2.0160 4.0000 1.0000
2.0240 4.0000 1.0000
2.0320 3.0000 1.0000
2.0400 5.0000 1.0000
2.0480 6.0000 1.0000
2.0560 2.0000 1.0000
2.0640 2.0000 1.0000
2.0720 6.0000 1.0000
2.0800 6.0000 1.0000
2.0880 2.0000 1.0000
2.0960 7.0000 1.0000
2.1040 6.0000 1.0000
2.1120 4.0000 1.0000
2.1200 6.0000 1.0000
2.1280 2.0000 1.0000
2.1360 8.0000 1.0000
2.1440 4.0000 1.0000
2.1520 7.0000 1.0000
2.1600 7.0000 1.0000
2.1680 8.0000 1.0000
2.1760 6.0000 1.0000
2.1840 2.0000 1.0000
2.1920 4.0000 1.0000
2.2000 5.0000 1.0000
2.2080 3.0000 1.0000
2.2160 4.0000 1.0000
2.2240 6.0000 1.0000
2.2320 4.0000 1.0000
2.2400 4.0000 1.0000
2.2480 0.0000 1.0000
2.2560 6.0000 1.0000
2.2640 3.0000 1.0000
2.2720 1.0000 1.0000
2.2800 3.0000 1.0000
2.2880 2.0000 1.0000
2.2960 5.0000 1.0000
2.3040 5.0000 1.0000
2.3120 7.0000 1.0000
2.3200 9.0000 1.0000
2.3280 3.0000 1.0000
2.3360 4.0000 1.0000
2.3440 7.0000 1.0000
2.3520 2.0000 1.0000
2.3600 1.0000 1.0000
2.3680 6.0000 1.0000
2.3760 6.0000 1.0000
2.3840 6.0000 1.0000
2.3920 8.0000 1.0000
2.4000 5.0000 1.0000
2.4080 1.0000 1.0000
2.4160 5.0000 1.0000
2.4240 3.0000 1.0000
2.4320 6.0000 1.0000
2.4400 3.0000 1.0000
2.4480 6.0000 1.0000
2.4560 6.0000 1.0000
2.4640 5.0000 1.0000
2.4720 3.0000 1.0000
2.4800 3.0000 1.0000
2.4880 8.0000 1.0000
2.4960 2.0000 1.0000
2.5040 12.0000 1.0000
2.5120 4.0000 1.0000
2.5200 5.0000 1.0000
2.5280 4.0000 1.0000
2.5360 2.0000 1.0000
2.5440 2.0000 1.0000
2.5520 4.0000 1.0000
2.5600 8.0000 1.0000
2.5680 4.0000 1.0000
2.5760 1.0000 1.0000
2.5840 4.0000 1.0000
2.5920 3.0000 1.0000
2.6000 4.0000 1.0000
2.6080 6.0000 1.0000
2.6160 2.0000 1.0000
2.6240 2.0000 1.0000
2.6320 0.0000 1.0000
2.6400 6.0000 1.0000
2.6480 1.0000 1.0000
2.6560 4.0000 1.0000
2.6640 6.0000 1.0000
2.6720 3.0000 1.0000
2.6800 4.0000 1.0000
2.6880 8.0000 1.0000
2.6960 4.0000 1.0000
2.7040 5.0000 1.0000
2.7120 2.0000 1.0000
2.7200 4.0000 1.0000
2.7280 5.0000 1.0000
2.7360 1.0000 1.0000
2.7440 2.0000 1.0000
2.7520 4.0000 1.0000
2.7600 4.0000 1.0000
2.7680 1.0000 1.0000
2.7760 4.0000 1.0000
2.7840 3.0000 1.0000
2.7920 3.0000 1.0000
2.8000 5.0000 1.0000
2.8080 3.0000 1.0000
2.8160 2.0000 1.0000
2.8240 3.0000 1.0000
2.8320 3.0000 1.0000
2.8400 7.0000 1.0000
2.8480 4.0000 1.0000
2.8560 5.0000 1.0000
2.8640 3.0000 1.0000
2.8720 2.0000 1.0000
2.8800 2.0000 1.0000
2.8880 4.0000 1.0000
2.8960 6.0000 1.0000
2.9040 3.0000 1.0000
2.9120 2.0000 1.0000
2.9200 2.0000 1.0000
2.9280 5.0000 1.0000
2.9360 3.0000 1.0000
2.9440 4.0000 1.0000
2.9520 2.0000 1.0000
2.9600 3.0000 1.0000
2.9680 2.0000 1.0000
2.9760 3.0000 1.0000
2.9840 4.0000 1.0000
2.9920 4.0000 1.0000
3.0000 5.0000 1.0000
3.0080 5.0000 1.0000
3.0160 4.0000 1.0000
3.0240 5.0000 1.0000
3.0320 6.0000 1.0000
3.0400 5.0000 1.0000
3.0480 2.0000 1.0000
3.0560 4.0000 1.0000
3.0640 9.0000 1.0000
3.0720 1.0000 1.0000
3.0800 2.0000 1.0000
3.0880 1.0000 1.0000
3.0960 6.0000 1.0000
3.1040 4.0000 1.0000
3.1120 6.0000 1.0000
3.1200 1.0000 1.0000
3.1280 2.0000 1.0000
3.1360 6.0000 1.0000
3.1440 2.0000 1.0000
3.1520 6.0000 1.0000
3.1600 3.0000 1.0000
3.1680 2.0000 1.0000
3.1760 1.0000 1.0000
3.1840 2.0000 1.0000
3.1920 5.0000 1.0000
3.2000 1.0000 1.0000
3.2080 0.0000 1.0000
3.2160 1.0000 1.0000
3.2240 3.0000 1.0000
3.2320 2.0000 1.0000
3.2400 3.0000 1.0000
3.2480 3.0000 1.0000
3.2560 3.0000 1.0000
3.2640 5.0000 1.0000
3.2720 6.0000 1.0000
3.2800 5.0000 1.0000
3.2880 4.0000 1.0000
3.2960 1.0000 1.0000
3.3040 3.0000 1.0000
3.3120 8.0000 1.0000
3.3200 1.0000 1.0000
3.3280 3.0000 1.0000
3.3360 2.0000 1.0000
3.3440 6.0000 1.0000
3.3520 2.0000 1.0000
3.3600 2.0000 1.0000
3.3680 2.0000 1.0000
3.3760 2.0000 1.0000
3.3840 3.0000 1.0000
3.3920 3.0000 1.0000
3.4000 4.0000 1.0000
3.4080 1.0000 1.0000
3.4160 8.0000 1.0000
3.4240 5.0000 1.0000
3.4320 3.0000 1.0000
3.4400 1.0000 1.0000
3.4480 4.0000 1.0000
3.4560 0.0000 1.0000
3.4640 1.0000 1.0000
3.4720 2.0000 1.0000
3.4800 3.0000 1.0000
3.4880 2.0000 1.0000
3.4960 3.0000 1.0000
3.5040 3.0000 1.0000
3.5120 4.0000 1.0000
3.5200 2.0000 1.0000
3.5280 1.0000 1.0000
3.5360 1.0000 1.0000
3.5440 2.0000 1.0000
3.5520 3.0000 1.0000
3.5600 5.0000 1.0000
3.5680 4.0000 1.0000
3.5760 8.0000 1.0000
3.5840 3.0000 1.0000
3.5920 4.0000 1.0000
3.6000 1.0000 1.0000
3.6080 1.0000 1.0000
3.6160 6.0000 1.0000
3.6240 0.0000 1.0000
3.6320 1.0000 1.0000
3.6400 1.0000 1.0000
3.6480 1.0000 1.0000
3.6560 0.0000 1.0000
3.6640 3.0000 1.0000
3.6720 1.0000 1.0000
3.6800 3.0000 1.0000
3.6880 3.0000 1.0000
3.6960 0.0000 1.0000
3.7040 4.0000 1.0000
3.7120 5.0000 1.0000
3.7200 2.0000 1.0000
3.7280 3.0000 1.0000
3.7360 5.0000 1.0000
3.7440 1.0000 1.0000
3.7520 5.0000 1.0000
3.7600 2.0000 1.0000
3.7680 2.0000 1.0000
3.7760 2.0000 1.0000
3.7840 0.0000 1.0000
3.7920 4.0000 1.0000
3.8000 4.0000 1.0000
3.8080 2.0000 1.0000
3.8160 6.0000 1.0000
3.8240 3.0000 1.0000
3.8320 3.0000 1.0000
3.8400 3.0000 1.0000
3.8480 4.0000 1.0000
3.8560 2.0000 1.0000
3.8640 2.0000 1.0000
3.8720 4.0000 1.0000
3.8800 2.0000 1.0000
3.8880 3.0000 1.0000
3.8960 3.0000 1.0000
3.9040 1.0000 1.0000
3.9120 3.0000 1.0000
3.9200 0.0000 1.0000
3.9280 3.0000 1.0000
3.9360 5.0000 1.0000
3.9440 2.0000 1.0000
3.9520 2.0000 1.0000
3.9600 1.0000 1.0000
3.9680 4.0000 1.0000
3.9760 2.0000 1.0000
3.9840 2.0000 1.0000
3.9920 1.0000 1.0000
4.0000 2.0000 1.0000
4.0080 2.0000 1.0000
4.0160 1.0000 1.0000
4.0240 4.0000 1.0000
4.0320 2.0000 1.0000
4.0400 2.0000 1.0000
4.0480 2.0000 1.0000
4.0560 1.0000 1.0000
4.0640 3.0000 1.0000
4.0720 4.0000 1.0000
4.0800 3.0000 1.0000
4.0880 0.0000 1.0000
4.0960 2.0000 1.0000
4.1040 2.0000 1.0000
4.1120 4.0000 1.0000
4.1200 2.0000 1.0000
4.1280 2.0000 1.0000
4.1360 4.0000 1.0000
4.1440 1.0000 1.0000
4.1520 1.0000 1.0000
4.1600 8.0000 1.0000
4.1680 3.0000 1.0000
4.1760 1.0000 1.0000
4.1840 3.0000 1.0000
4.1920 5.0000 1.0000
4.2000 1.0000 1.0000
4.2080 0.0000 1.0000
4.2160 1.0000 1.0000
4.2240 4.0000 1.0000
4.2320 4.0000 1.0000
4.2400 2.0000 1.0000
4.2480 3.0000 1.0000
4.2560 2.0000 1.0000
4.2640 4.0000 1.0000
4.2720 0.0000 1.0000
4.2800 1.0000 1.0000
4.2880 3.0000 1.0000
4.2960 2.0000 1.0000
4.3040 3.0000 1.0000
4.3120 2.0000 1.0000
4.3200 0.0000 1.0000
4.3280 3.0000 1.0000
4.3360 1.0000 1.0000
4.3440 4.0000 1.0000
4.3520 2.0000 1.0000
4.3600 1.0000 1.0000
4.3680 2.0000 1.0000
4.3760 0.0000 1.0000
4.3840 1.0000 1.0000
4.3920 1.0000 1.0000
4.4000 3.0000 1.0000
4.4080 2.0000 1.0000
4.4160 4.0000 1.0000
4.4240 1.0000 1.0000
4.4320 2.0000 1.0000
4.4400 1.0000 1.0000
4.4480 0.0000 1.0000
4.4560 3.0000 1.0000
4.4640 2.0000 1.0000
4.4720 3.0000 1.0000
4.4800 2.0000 1.0000
4.4880 3.0000 1.0000
4.4960 3.0000 1.0000
4.5040 1.0000 1.0000
4.5120 2.0000 1.0000
4.5200 2.0000 1.0000
4.5280 2.0000 1.0000
4.5360 2.0000 1.0000
4.5440 0.0000 1.0000
4.5520 1.0000 1.0000
4.5600 2.0000 1.0000
4.5680 2.0000 1.0000
4.5760 2.0000 1.0000
4.5840 3.0000 1.0000
4.5920 0.0000 1.0000
4.6000 3.0000 1.0000
4.6080 1.0000 1.0000
4.6160 3.0000 1.0000
4.6240 2.0000 1.0000
4.6320 3.0000 1.0000
4.6400 1.0000 1.0000
4.6480 1.0000 1.0000
4.6560 1.0000 1.0000
4.6640 1.0000 1.0000
4.6720 1.0000 1.0000
4.6800 1.0000 1.0000
4.6880 5.0000 1.0000
4.6960 4.0000 1.0000
4.7040 1.0000 1.0000
4.7120 7.0000 1.0000
4.7200 1.0000 1.0000
4.7280 3.0000 1.0000
4.7360 4.0000 1.0000
4.7440 0.0000 1.0000
4.7520 1.0000 1.0000
4.7600 2.0000 1.0000
4.7680 2.0000 1.0000
4.7760 2.0000 1.0000
4.7840 3.0000 1.0000
4.7920 1.0000 1.0000
4.8000 1.0000 1.0000
4.8080 1.0000 1.0000
4.8160 2.0000 1.0000
4.8240 3.0000 1.0000
4.8320 1.0000 1.0000
4.8400 2.0000 1.0000
4.8480 2.0000 1.0000
4.8560 3.0000 1.0000
4.8640 0.0000 1.0000
4.8720 1.0000 1.0000
4.8800 1.0000 1.0000
4.8880 2.0000 1.0000
4.8960 6.0000 1.0000
4.9040 1.0000 1.0000
4.9120 1.0000 1.0000
4.9200 2.0000 1.0000
4.9280 1.0000 1.0000
4.9360 2.0000 1.0000
4.9440 3.0000 1.0000
4.9520 3.0000 1.0000
4.9600 1.0000 1.0000
4.9680 4.0000 1.0000
4.9760 1.0000 1.0000
4.9840 3.0000 1.0000
4.9920 2.0000 1.0000
5.0000 3.0000 1.0000
5.0080 0.0000 1.0000
5.0160 3.0000 1.0000
5.0240 0.0000 1.0000
5.0320 1.0000 1.0000
5.0400 6.0000 1.0000
5.0480 1.0000 1.0000
5.0560 1.0000 1.0000
5.0640 2.0000 1.0000
5.0720 0.0000 1.0000
5.0800 3.0000 1.0000
5.0880 3.0000 1.0000
5.0960 0.0000 1.0000
5.1040 2.0000 1.0000
5.1120 3.0000 1.0000
5.1200 0.0000 1.0000
5.1280 3.0000 1.0000
5.1360 1.0000 1.0000
5.1440 2.0000 1.0000
5.1520 2.0000 1.0000
5.1600 2.0000 1.0000
5.1680 3.0000 1.0000
5.1760 3.0000 1.0000
5.1840 7.0000 1.0000
5.1920 2.0000 1.0000
5.2000 0.0000 1.0000
5.2080 2.0000 1.0000
5.2160 3.0000 1.0000
5.2240 2.0000 1.0000
5.2320 0.0000 1.0000
5.2400 2.0000 1.0000
5.2480 4.0000 1.0000
5.2560 2.0000 1.0000
5.2640 1.0000 1.0000
5.2720 1.0000 1.0000
5.2800 2.0000 1.0000
5.2880 2.0000 1.0000
5.2960 2.0000 1.0000
5.3040 4.0000 1.0000
5.3120 0.0000 1.0000
5.3200 2.0000 1.0000
5.3280 3.0000 1.0000
5.3360 2.0000 1.0000
5.3440 3.0000 1.0000
5.3520 0.0000 1.0000
5.3600 4.0000 1.0000
5.3680 0.0000 1.0000
5.3760 2.0000 1.0000
5.3840 1.0000 1.0000
5.3920 1.0000 1.0000
5.4000 3.0000 1.0000
5.4080 2.0000 1.0000
5.4160 3.0000 1.0000
5.4240 0.0000 1.0000
5.4320 4.0000 1.0000
5.4400 3.0000 1.0000
5.4480 3.0000 1.0000
5.4560 2.0000 1.0000
5.4640 3.0000 1.0000
5.4720 4.0000 1.0000
5.4800 5.0000 1.0000
5.4880 2.0000 1.0000
5.4960 1.0000 1.0000
5.5040 2.0000 1.0000
5.5120 2.0000 1.0000
5.5200 0.0000 1.0000
5.5280 0.0000 1.0000
5.5360 5.0000 1.0000
5.5440 1.0000 1.0000
5.5520 3.0000 1.0000
5.5600 2.0000 1.0000
5.5680 2.0000 1.0000
5.5760 8.0000 1.0000
5.5840 4.0000 1.0000
5.5920 3.0000 1.0000
5.6000 2.0000 1.0000
5.6080 4.0000 1.0000
5.6160 2.0000 1.0000
5.6240 2.0000 1.0000
5.6320 3.0000 1.0000
5.6400 2.0000 1.0000
5.6480 1.0000 1.0000
5.6560 3.0000 1.0000
5.6640 2.0000 1.0000
5.6720 2.0000 1.0000
5.6800 3.0000 1.0000
5.6880 3.0000 1.0000
5.6960 2.0000 1.0000
5.7040 2.0000 1.0000
5.7120 0.0000 1.0000
5.7200 3.0000 1.0000
5.7280 1.0000 1.0000
5.7360 1.0000 1.0000
5.7440 3.0000 1.0000
5.7520 2.0000 1.0000
5.7600 2.0000 1.0000
5.7680 2.0000 1.0000
5.7760 4.0000 1.0000
5.7840 0.0000 1.0000
5.7920 0.0000 1.0000
5.8000 0.0000 1.0000
5.8080 3.0000 1.0000
5.8160 1.0000 1.0000
5.8240 3.0000 1.0000
5.8320 0.0000 1.0000
5.8400 2.0000 1.0000
5.8480 3.0000 1.0000
5.8560 3.0000 1.0000
5.8640 1.0000 1.0000
5.8720 0.0000 1.0000
5.8800 0.0000 1.0000
5.8880 2.0000 1.0000
5.8960 2.0000 1.0000
5.9040 3.0000 1.0000
5.9120 5.0000 1.0000
5.9200 2.0000 1.0000
5.9280 1.0000 1.0000
5.9360 1.0000 1.0000
5.9440 1.0000 1.0000
5.9520 3.0000 1.0000
5.9600 1.0000 1.0000
5.9680 1.0000 1.0000
5.9760 4.0000 1.0000
5.9840 5.0000 1.0000
5.9920 2.0000 1.0000
6.0000 0.0000 1.0000
*RAS_INT_END
*RAS_TEMPERATURE_START
*RAS_TEMPERATURE_END
*RAS_DATA_END